Workbook

Sheet Raw Data
A1: ID | B1: model | C1: temperature | D1: top_p | E1: top_k | F1: code | G1: result | H1: true_count | I1: false_count | J1: execution_time | K1: memory_usage_MB | L1: algorithmic_complexity | M1: Total Tests | N1: Accuracy | O1: Numeric Complexity
A2: 1 | B2: gemini-2.0-flash-lite | C2: 0 | D2: 0.1 | E2: 10 | F2: class ListNode: def __init__(self, val=0, next=None): self.val = val self.next = next def addTwoNumbers(l1: ListNode, l2: ListNode) -> ListNode: """ Adds two numbers represented as linked lists. Args: l1: The first linked list. l2: The second linked list. Returns: The sum as a linked list. """ dummy_head = ListNode(0) current = dummy_head carry = 0 while l1 or l2 or carry: sum_val = carry if l1: sum_val += l1.val l1 = l1.next if l2: sum_val += l2.val l2 = l2.next carry = sum_val // 10 current.next = ListNode(sum_val % 10) current = current.next return dummy_head.next def list_to_linked_list(lst): """Converts a list to a linked list.""" dummy_head = ListNode(0) current = dummy_head for val in lst: current.next = ListNode(val) current = current.next return dummy_head.next def linked_list_to_list(head): """Converts a linked list to a list.""" result = [] current = head while current: result.append(current.val) current = current.next return result def test_add_two_numbers(): """Tests the addTwoNumbers function.""" tests = [ ([2, 4, 3], [5, 6, 4], [7, 0, 8]), ([0], [0], [0]), ([9, 9, 9, 9, 9, 9, 9], [9, 9, 9, 9], [8, 9, 9, 9, 0, 0, 0, 1]), ([1, 2, 3], [4, 5, 6], [5, 7, 9]), ([1], [9, 9], [0, 0, 1]) ] correct_tests = 0 for i, (l1_list, l2_list, expected_list) in enumerate(tests): l1 = list_to_linked_list(l1_list) l2 = list_to_linked_list(l2_list) result_linked_list = addTwoNumbers(l1, l2) result_list = linked_list_to_list(result_linked_list) if result_list == expected_list: print(True) correct_tests += 1 else: print(False) print(f"{correct_tests}/{len(tests)}") if __name__ == '__main__': test_add_two_numbers() | G2: True_x000D_ True_x000D_ True_x000D_ True_x000D_ True_x000D_ 5/5 | H2: 5 | I2: 0 | J2: 0.14 | K2: 2.02 | L2: loops: 4, conditionals: 4 | M2: =H2+I2 -> 0 | N2: =IF(M2>0,H2/M2,"") -> 0 | O2: =VALUE(TRIM(MID(L2,FIND(":",L2)+1,FIND(",",L2)-FIND(":",L2)-1)))+VALUE(TRIM(MID(L2,FIND("conditionals:",L2)+13,LEN(L2)))) -> 0
A3: 2 | B3: gemini-2.0-flash-lite | C3: 0 | D3: 0.1 | E3: 10 | F3: def lengthOfLongestSubstring(s: str) -> int: """ Finds the length of the longest substring without repeating characters. Args: s: The input string. Returns: The length of the longest substring without repeating characters. """ if not s: return 0 max_length = 0 start = 0 char_index_map = {} # Store the index of each character for end, char in enumerate(s): if char in char_index_map and char_index_map[char] >= start: # Repeating character found within the current window start = char_index_map[char] + 1 char_index_map[char] = end max_length = max(max_length, end - start + 1) return max_length def test_length_of_longest_substring(): """Tests the lengthOfLongestSubstring function.""" tests = [ ("abcabcbb", 3), ("bbbbb", 1), ("pwwkew", 3), ("", 0), (" ", 1), ("au", 2), ("dvdf", 3), ("tmmzuxt", 5) ] correct_tests = 0 for s, expected_length in tests: result = lengthOfLongestSubstring(s) if result == expected_length: print(True) correct_tests += 1 else: print(False) print(f"{correct_tests}/{len(tests)}") if __name__ == '__main__': test_length_of_longest_substring() | G3: True_x000D_ True_x000D_ True_x000D_ True_x000D_ True_x000D_ True_x000D_ True_x000D_ True_x000D_ 8/8 | H3: 8 | I3: 0 | J3: 0.11 | K3: 2.01 | L3: loops: 2, conditionals: 4 | M3: =H3+I3 -> 0 | N3: =IF(M3>0,H3/M3,"") -> 0 | O3: =VALUE(TRIM(MID(L3,FIND(":",L3)+1,FIND(",",L3)-FIND(":",L3)-1)))+VALUE(TRIM(MID(L3,FIND("conditionals:",L3)+13,LEN(L3)))) -> 0
A4: 3 | B4: gemini-2.0-flash-lite | C4: 0 | D4: 0.1 | E4: 10 | F4: def findMedianSortedArrays(nums1: list[int], nums2: list[int]) -> float: """ Finds the median of two sorted arrays. Args: nums1: The first sorted array. nums2: The second sorted array. Returns: The median of the two sorted arrays. """ merged_array = sorted(nums1 + nums2) merged_length = len(merged_array) if merged_length == 0: return 0.0 if merged_length % 2 == 0: # Even length, median is the average of the middle two elements mid1 = merged_array[merged_length // 2 - 1] mid2 = merged_array[merged_length // 2] return (mid1 + mid2) / 2.0 else: # Odd length, median is the middle element return float(merged_array[merged_length // 2]) def test_find_median_sorted_arrays(): """Tests the findMedianSortedArrays function.""" tests = [ ([1, 3], [2], 2.0), ([1, 2], [3, 4], 2.5), ([0, 0], [0, 0], 0.0), ([], [1], 1.0), ([2], [], 2.0), ([1, 2, 3], [4, 5, 6], 3.5), ([4, 5, 6], [1, 2, 3], 3.5), ([1, 3], [2, 7], 3.0), ([1, 2, 3], [2, 4, 6], 2.5) ] correct_tests = 0 for nums1, nums2, expected_median in tests: result = findMedianSortedArrays(nums1, nums2) if abs(result - expected_median) < 1e-5: # Use a small tolerance for floating-point comparisons print(True) correct_tests += 1 else: print(False) print(f"{correct_tests}/{len(tests)}") if __name__ == '__main__': test_find_median_sorted_arrays() | G4: True_x000D_ True_x000D_ True_x000D_ True_x000D_ True_x000D_ True_x000D_ True_x000D_ False_x000D_ True_x000D_ 8/9 | H4: 8 | I4: 1 | J4: 0.11 | K4: 2.01 | L4: loops: 1, conditionals: 4 | M4: =H4+I4 -> 0 | N4: =IF(M4>0,H4/M4,"") -> 0 | O4: =VALUE(TRIM(MID(L4,FIND(":",L4)+1,FIND(",",L4)-FIND(":",L4)-1)))+VALUE(TRIM(MID(L4,FIND("conditionals:",L4)+13,LEN(L4)))) -> 0
A5: 4 | B5: gemini-2.0-flash-lite | C5: 0 | D5: 0.1 | E5: 10 | F5: def isMatch(s: str, p: str) -> bool: """ Implements regular expression matching with support for '.' and '*'. Args: s: The input string. p: The pattern. Returns: True if the pattern matches the entire input string, False otherwise. """ s_len = len(s) p_len = len(p) # dp[i][j] represents whether s[:i] matches p[:j] dp = [[False] * (p_len + 1) for _ in range(s_len + 1)] # Base case: empty string matches empty pattern dp[0][0] = True # Handle patterns like a*, a*b*, a*b*c* for j in range(1, p_len + 1): if p[j - 1] == '*': dp[0][j] = dp[0][j - 2] # '*' matches zero occurrences of the preceding character # Fill the dp table for i in range(1, s_len + 1): for j in range(1, p_len + 1): if p[j - 1] == '.' or p[j - 1] == s[i - 1]: # Current characters match dp[i][j] = dp[i - 1][j - 1] elif p[j - 1] == '*': # '*' case dp[i][j] = dp[i][j - 2] # '*' matches zero occurrences of the preceding character if p[j - 2] == '.' or p[j - 2] == s[i - 1]: dp[i][j] = dp[i][j] or dp[i - 1][j] # '*' matches one or more occurrences else: # Characters don't match dp[i][j] = False return dp[s_len][p_len] def test_isMatch(): """Tests the isMatch function.""" tests = [ ("aa", "a", False), ("aa", "a*", True), ("ab", ".*", True), ("aab", "c*a*b", True), ("mississippi", "mis*is*p*.", False), ("a", "ab*", True), ("abc", ".*", True), ("abc", "a.c", True), ("abc", "a.d", False), ("aaa", "a*a", True), ("aaa", "ab*a*c*a", True), ("a", ".*..", False), ("ab", ".*c", False), ("aaaaaaaaaaaaab", "a*a*a*a*a*a*a*a*a*a*c", False) ] correct_tests = 0 for s, p, expected in tests: result = isMatch(s, p) if result == expected: print(True) correct_tests += 1 else: print(False) print(f"{correct_tests}/{len(tests)}") if __name__ == '__main__': test_isMatch() | G5: True_x000D_ True_x000D_ True_x000D_ True_x000D_ True_x000D_ True_x000D_ True_x000D_ True_x000D_ True_x000D_ True_x000D_ True_x000D_ True_x000D_ True_x000D_ True_x000D_ 14/14 | H5: 14 | I5: 0 | J5: 0.11 | K5: 2.05 | L5: loops: 4, conditionals: 6 | M5: =H5+I5 -> 0 | N5: =IF(M5>0,H5/M5,"") -> 0 | O5: =VALUE(TRIM(MID(L5,FIND(":",L5)+1,FIND(",",L5)-FIND(":",L5)-1)))+VALUE(TRIM(MID(L5,FIND("conditionals:",L5)+13,LEN(L5)))) -> 0
A6: 5 | B6: gemini-2.0-flash-lite | C6: 0 | D6: 0.1 | E6: 10 | F6: import heapq class ListNode: def __init__(self, val=0, next=None): self.val = val self.next = next def mergeKLists(lists: list[ListNode]) -> ListNode: """ Merges k sorted linked lists into one sorted linked list. Args: lists: A list of sorted linked lists. Returns: The merged sorted linked list. """ # Use a min-heap to efficiently merge the lists heap = [] for i, head in enumerate(lists): if head: heapq.heappush(heap, (head.val, i, head)) # (value, list_index, node) dummy_head = ListNode() current = dummy_head while heap: val, list_index, node = heapq.heappop(heap) current.next = node current = current.next if node.next: heapq.heappush(heap, (node.next.val, list_index, node.next)) return dummy_head.next def list_to_linked_list(lst): """Converts a list to a linked list.""" dummy_head = ListNode() current = dummy_head for val in lst: current.next = ListNode(val) current = current.next return dummy_head.next def linked_list_to_list(head): """Converts a linked list to a list.""" result = [] current = head while current: result.append(current.val) current = current.next return result def test_merge_k_lists(): """Tests the mergeKLists function.""" tests = [ ([[1, 4, 5], [1, 3, 4], [2, 6]], [1, 1, 2, 3, 4, 4, 5, 6]), ([], []), ([[]], []), ([[1, 2, 3], [], [4, 5, 6]], [1, 2, 3, 4, 5, 6]), ([[-1, 5, 11], [6, 10], [2, 3, 4, 7, 8, 9]], [-1, 2, 3, 4, 5, 6, 7, 8, 9, 10, 11]), ([[] , [1]], [1]) ] correct_tests = 0 for lists_input, expected_output in tests: lists = [list_to_linked_list(lst) for lst in lists_input] merged_list = mergeKLists(lists) result = linked_list_to_list(merged_list) if result == expected_output: print(True) correct_tests += 1 else: print(False) print(f"{correct_tests}/{len(tests)}") if __name__ == '__main__': test_merge_k_lists() | G6: True_x000D_ True_x000D_ True_x000D_ True_x000D_ True_x000D_ True_x000D_ 6/6 | H6: 6 | I6: 0 | J6: 0.11 | K6: 2 | L6: loops: 5, conditionals: 4 | M6: =H6+I6 -> 0 | N6: =IF(M6>0,H6/M6,"") -> 0 | O6: =VALUE(TRIM(MID(L6,FIND(":",L6)+1,FIND(",",L6)-FIND(":",L6)-1)))+VALUE(TRIM(MID(L6,FIND("conditionals:",L6)+13,LEN(L6)))) -> 0
A7: 1 | B7: gemini-2.0-flash-lite | C7: 0 | D7: 0.5 | E7: 30 | F7: class ListNode: def __init__(self, val=0, next=None): self.val = val self.next = next def addTwoNumbers(l1: ListNode, l2: ListNode) -> ListNode: """ Adds two numbers represented as linked lists. Args: l1: The first linked list. l2: The second linked list. Returns: The sum as a linked list. """ dummy_head = ListNode(0) current = dummy_head carry = 0 while l1 or l2 or carry: sum_val = carry if l1: sum_val += l1.val l1 = l1.next if l2: sum_val += l2.val l2 = l2.next carry = sum_val // 10 current.next = ListNode(sum_val % 10) current = current.next return dummy_head.next def list_to_linked_list(lst): """Converts a list to a linked list.""" dummy_head = ListNode(0) current = dummy_head for val in lst: current.next = ListNode(val) current = current.next return dummy_head.next def linked_list_to_list(head): """Converts a linked list to a list.""" result = [] current = head while current: result.append(current.val) current = current.next return result def test_add_two_numbers(): """Tests the addTwoNumbers function.""" tests = [ ([2, 4, 3], [5, 6, 4], [7, 0, 8]), ([0], [0], [0]), ([9, 9, 9, 9, 9, 9, 9], [9, 9, 9, 9], [8, 9, 9, 9, 0, 0, 0, 1]), ([1, 2, 3], [4, 5, 6], [5, 7, 9]), ([1], [9, 9], [0, 0, 1]) ] correct_tests = 0 for i, (l1_list, l2_list, expected_list) in enumerate(tests): l1 = list_to_linked_list(l1_list) l2 = list_to_linked_list(l2_list) result_linked_list = addTwoNumbers(l1, l2) result_list = linked_list_to_list(result_linked_list) if result_list == expected_list: print(True) correct_tests += 1 else: print(False) print(f"{correct_tests}/{len(tests)}") if __name__ == '__main__': test_add_two_numbers() | G7: True_x000D_ True_x000D_ True_x000D_ True_x000D_ True_x000D_ 5/5 | H7: 5 | I7: 0 | J7: 0.11 | K7: 2.01 | L7: loops: 4, conditionals: 4 | M7: =H7+I7 -> 0 | N7: =IF(M7>0,H7/M7,"") -> 0 | O7: =VALUE(TRIM(MID(L7,FIND(":",L7)+1,FIND(",",L7)-FIND(":",L7)-1)))+VALUE(TRIM(MID(L7,FIND("conditionals:",L7)+13,LEN(L7)))) -> 0
A8: 2 | B8: gemini-2.0-flash-lite | C8: 0 | D8: 0.5 | E8: 30 | F8: def lengthOfLongestSubstring(s: str) -> int: """ Finds the length of the longest substring without repeating characters. Args: s: The input string. Returns: The length of the longest substring without repeating characters. """ if not s: return 0 max_length = 0 start = 0 char_index_map = {} # Store the index of each character for end, char in enumerate(s): if char in char_index_map and char_index_map[char] >= start: # Repeating character found within the current window start = char_index_map[char] + 1 char_index_map[char] = end max_length = max(max_length, end - start + 1) return max_length def test_length_of_longest_substring(): """Tests the lengthOfLongestSubstring function.""" tests = [ ("abcabcbb", 3), ("bbbbb", 1), ("pwwkew", 3), ("", 0), (" ", 1), ("au", 2), ("dvdf", 3), ("tmmzuxt", 5) ] correct_tests = 0 for s, expected_length in tests: result = lengthOfLongestSubstring(s) if result == expected_length: print(True) correct_tests += 1 else: print(False) print(f"{correct_tests}/{len(tests)}") if __name__ == '__main__': test_length_of_longest_substring() | G8: True_x000D_ True_x000D_ True_x000D_ True_x000D_ True_x000D_ True_x000D_ True_x000D_ True_x000D_ 8/8 | H8: 8 | I8: 0 | J8: 0.11 | K8: 2.01 | L8: loops: 2, conditionals: 4 | M8: =H8+I8 -> 0 | N8: =IF(M8>0,H8/M8,"") -> 0 | O8: =VALUE(TRIM(MID(L8,FIND(":",L8)+1,FIND(",",L8)-FIND(":",L8)-1)))+VALUE(TRIM(MID(L8,FIND("conditionals:",L8)+13,LEN(L8)))) -> 0
A9: 3 | B9: gemini-2.0-flash-lite | C9: 0 | D9: 0.5 | E9: 30 | F9: def findMedianSortedArrays(nums1: list[int], nums2: list[int]) -> float: """ Finds the median of two sorted arrays. Args: nums1: The first sorted array. nums2: The second sorted array. Returns: The median of the two sorted arrays. """ merged_array = sorted(nums1 + nums2) merged_length = len(merged_array) if merged_length == 0: return 0.0 if merged_length % 2 == 0: # Even length, median is the average of the middle two elements mid1 = merged_array[merged_length // 2 - 1] mid2 = merged_array[merged_length // 2] return (mid1 + mid2) / 2.0 else: # Odd length, median is the middle element return float(merged_array[merged_length // 2]) def test_find_median_sorted_arrays(): """Tests the findMedianSortedArrays function.""" tests = [ ([1, 3], [2], 2.0), ([1, 2], [3, 4], 2.5), ([0, 0], [0, 0], 0.0), ([], [1], 1.0), ([2], [], 2.0), ([1, 2, 3], [4, 5, 6], 3.5), ([4, 5, 6], [1, 2, 3], 3.5), ([1, 3], [2, 7], 3.0), ([1, 2, 3], [2, 4, 6], 2.5) ] correct_tests = 0 for nums1, nums2, expected_median in tests: result = findMedianSortedArrays(nums1, nums2) if abs(result - expected_median) < 1e-5: # Use a small tolerance for floating-point comparisons print(True) correct_tests += 1 else: print(False) print(f"{correct_tests}/{len(tests)}") if __name__ == '__main__': test_find_median_sorted_arrays() | G9: True_x000D_ True_x000D_ True_x000D_ True_x000D_ True_x000D_ True_x000D_ True_x000D_ False_x000D_ True_x000D_ 8/9 | H9: 8 | I9: 1 | J9: 0.11 | K9: 2.01 | L9: loops: 1, conditionals: 4 | M9: =H9+I9 -> 0 | N9: =IF(M9>0,H9/M9,"") -> 0 | O9: =VALUE(TRIM(MID(L9,FIND(":",L9)+1,FIND(",",L9)-FIND(":",L9)-1)))+VALUE(TRIM(MID(L9,FIND("conditionals:",L9)+13,LEN(L9)))) -> 0
A10: 4 | B10: gemini-2.0-flash-lite | C10: 0 | D10: 0.5 | E10: 30 | F10: def isMatch(s: str, p: str) -> bool: """ Implements regular expression matching with support for '.' and '*'. Args: s: The input string. p: The pattern. Returns: True if the pattern matches the entire input string, False otherwise. """ s_len = len(s) p_len = len(p) # dp[i][j] represents whether s[:i] matches p[:j] dp = [[False] * (p_len + 1) for _ in range(s_len + 1)] # Base case: empty string matches empty pattern dp[0][0] = True # Handle patterns like a*, a*b*, a*b*c* for j in range(1, p_len + 1): if p[j - 1] == '*': dp[0][j] = dp[0][j - 2] # '*' matches zero occurrences of the preceding character # Fill the dp table for i in range(1, s_len + 1): for j in range(1, p_len + 1): if p[j - 1] == '.' or p[j - 1] == s[i - 1]: # Current characters match dp[i][j] = dp[i - 1][j - 1] elif p[j - 1] == '*': # '*' case dp[i][j] = dp[i][j - 2] # '*' matches zero occurrences of the preceding character if p[j - 2] == '.' or p[j - 2] == s[i - 1]: dp[i][j] = dp[i][j] or dp[i - 1][j] # '*' matches one or more occurrences else: # Characters don't match dp[i][j] = False return dp[s_len][p_len] def test_isMatch(): """Tests the isMatch function.""" tests = [ ("aa", "a", False), ("aa", "a*", True), ("ab", ".*", True), ("aab", "c*a*b", True), ("mississippi", "mis*is*p*.", False), ("a", "ab*", True), ("abc", ".*", True), ("abc", "a.c", True), ("abc", "a.d", False), ("aaa", "a*a", True), ("aaa", "ab*a*c*a", True), ("a", ".*..", False), ("ab", ".*c", False), ("aaaaaaaaaaaaab", "a*a*a*a*a*a*a*a*a*a*c", False) ] correct_tests = 0 for s, p, expected in tests: result = isMatch(s, p) if result == expected: print(True) correct_tests += 1 else: print(False) print(f"{correct_tests}/{len(tests)}") if __name__ == '__main__': test_isMatch() | G10: True_x000D_ True_x000D_ True_x000D_ True_x000D_ True_x000D_ True_x000D_ True_x000D_ True_x000D_ True_x000D_ True_x000D_ True_x000D_ True_x000D_ True_x000D_ True_x000D_ 14/14 | H10: 14 | I10: 0 | J10: 0.11 | K10: 2.04 | L10: loops: 4, conditionals: 6 | M10: =H10+I10 -> 0 | N10: =IF(M10>0,H10/M10,"") -> 0 | O10: =VALUE(TRIM(MID(L10,FIND(":",L10)+1,FIND(",",L10)-FIND(":",L10)-1)))+VALUE(TRIM(MID(L10,FIND("conditionals:",L10)+13,LEN(L10)))) -> 0
A11: 5 | B11: gemini-2.0-flash-lite | C11: 0 | D11: 0.5 | E11: 30 | F11: import heapq class ListNode: def __init__(self, val=0, next=None): self.val = val self.next = next def mergeKLists(lists: list[ListNode]) -> ListNode: """ Merges k sorted linked lists into one sorted linked list. Args: lists: A list of sorted linked lists. Returns: The merged sorted linked list. """ # Use a min-heap to efficiently merge the lists heap = [] for i, head in enumerate(lists): if head: heapq.heappush(heap, (head.val, i, head)) # (value, list_index, node) dummy_head = ListNode() current = dummy_head while heap: val, list_index, node = heapq.heappop(heap) current.next = node current = current.next if node.next: heapq.heappush(heap, (node.next.val, list_index, node.next)) return dummy_head.next def list_to_linked_list(lst): """Converts a list to a linked list.""" dummy_head = ListNode() current = dummy_head for val in lst: current.next = ListNode(val) current = current.next return dummy_head.next def linked_list_to_list(head): """Converts a linked list to a list.""" result = [] current = head while current: result.append(current.val) current = current.next return result def test_merge_k_lists(): """Tests the mergeKLists function.""" tests = [ ([[1, 4, 5], [1, 3, 4], [2, 6]], [1, 1, 2, 3, 4, 4, 5, 6]), ([], []), ([[]], []), ([[1, 2, 3], [], [4, 5, 6]], [1, 2, 3, 4, 5, 6]), ([[-1, 5, 11], [6, 10], [2, 3, 4, 7, 8, 9]], [-1, 2, 3, 4, 5, 6, 7, 8, 9, 10, 11]), ([[] , [1]], [1]) ] correct_tests = 0 for lists_input, expected_output in tests: lists = [list_to_linked_list(lst) for lst in lists_input] merged_list = mergeKLists(lists) result = linked_list_to_list(merged_list) if result == expected_output: print(True) correct_tests += 1 else: print(False) print(f"{correct_tests}/{len(tests)}") if __name__ == '__main__': test_merge_k_lists() | G11: True_x000D_ True_x000D_ True_x000D_ True_x000D_ True_x000D_ True_x000D_ 6/6 | H11: 6 | I11: 0 | J11: 0.11 | K11: 2.05 | L11: loops: 5, conditionals: 4 | M11: =H11+I11 -> 0 | N11: =IF(M11>0,H11/M11,"") -> 0 | O11: =VALUE(TRIM(MID(L11,FIND(":",L11)+1,FIND(",",L11)-FIND(":",L11)-1)))+VALUE(TRIM(MID(L11,FIND("conditionals:",L11)+13,LEN(L11)))) -> 0
A12: 1 | B12: gemini-2.0-flash-lite | C12: 0 | D12: 0.95 | E12: 100 | F12: class ListNode: def __init__(self, val=0, next=None): self.val = val self.next = next def addTwoNumbers(l1: ListNode, l2: ListNode) -> ListNode: """ Adds two numbers represented as linked lists. Args: l1: The first linked list. l2: The second linked list. Returns: The sum as a linked list. """ dummy_head = ListNode(0) current = dummy_head carry = 0 while l1 or l2 or carry: sum_val = carry if l1: sum_val += l1.val l1 = l1.next if l2: sum_val += l2.val l2 = l2.next carry = sum_val // 10 current.next = ListNode(sum_val % 10) current = current.next return dummy_head.next def list_to_linked_list(lst): """Converts a list to a linked list.""" dummy_head = ListNode(0) current = dummy_head for val in lst: current.next = ListNode(val) current = current.next return dummy_head.next def linked_list_to_list(head): """Converts a linked list to a list.""" result = [] current = head while current: result.append(current.val) current = current.next return result def test_add_two_numbers(): """Tests the addTwoNumbers function.""" tests = [ ([2, 4, 3], [5, 6, 4], [7, 0, 8]), ([0], [0], [0]), ([9, 9, 9, 9, 9, 9, 9], [9, 9, 9, 9], [8, 9, 9, 9, 0, 0, 0, 1]), ([1, 2, 3], [4, 5, 6], [5, 7, 9]), ([1], [9, 9], [0, 0, 1]) ] correct_tests = 0 for i, (l1_list, l2_list, expected_list) in enumerate(tests): l1 = list_to_linked_list(l1_list) l2 = list_to_linked_list(l2_list) result_linked_list = addTwoNumbers(l1, l2) result_list = linked_list_to_list(result_linked_list) if result_list == expected_list: print(True) correct_tests += 1 else: print(False) print(f"{correct_tests}/{len(tests)}") if __name__ == '__main__': test_add_two_numbers() | G12: True_x000D_ True_x000D_ True_x000D_ True_x000D_ True_x000D_ 5/5 | H12: 5 | I12: 0 | J12: 0.11 | K12: 2.01 | L12: loops: 4, conditionals: 4 | M12: =H12+I12 -> 0 | N12: =IF(M12>0,H12/M12,"") -> 0 | O12: =VALUE(TRIM(MID(L12,FIND(":",L12)+1,FIND(",",L12)-FIND(":",L12)-1)))+VALUE(TRIM(MID(L12,FIND("conditionals:",L12)+13,LEN(L12)))) -> 0
A13: 2 | B13: gemini-2.0-flash-lite | C13: 0 | D13: 0.95 | E13: 100 | F13: def lengthOfLongestSubstring(s: str) -> int: """ Finds the length of the longest substring without repeating characters. Args: s: The input string. Returns: The length of the longest substring without repeating characters. """ if not s: return 0 max_length = 0 start = 0 char_index_map = {} # Store the index of each character for end, char in enumerate(s): if char in char_index_map and char_index_map[char] >= start: # Repeating character found within the current window start = char_index_map[char] + 1 char_index_map[char] = end max_length = max(max_length, end - start + 1) return max_length def test_length_of_longest_substring(): """Tests the lengthOfLongestSubstring function.""" tests = [ ("abcabcbb", 3), ("bbbbb", 1), ("pwwkew", 3), ("", 0), (" ", 1), ("au", 2), ("dvdf", 3), ("abba", 2) ] correct_tests = 0 for s, expected_length in tests: result = lengthOfLongestSubstring(s) if result == expected_length: print(True) correct_tests += 1 else: print(False) print(f"{correct_tests}/{len(tests)}") if __name__ == '__main__': test_length_of_longest_substring() | G13: True_x000D_ True_x000D_ True_x000D_ True_x000D_ True_x000D_ True_x000D_ True_x000D_ True_x000D_ 8/8 | H13: 8 | I13: 0 | J13: 0.11 | K13: 2.01 | L13: loops: 2, conditionals: 4 | M13: =H13+I13 -> 0 | N13: =IF(M13>0,H13/M13,"") -> 0 | O13: =VALUE(TRIM(MID(L13,FIND(":",L13)+1,FIND(",",L13)-FIND(":",L13)-1)))+VALUE(TRIM(MID(L13,FIND("conditionals:",L13)+13,LEN(L13)))) -> 0
... A181: 5 | B181: gemini-2.0-pro-exp-02-05 | C181: 2 | D181: 0.95 | E181: 100 | F181: class ListNode: def __init__(self, val=0, next=None): self.val = val self.next = next def mergeKLists(lists): import heapq dummy = ListNode(-1) tail = dummy heap = [] for i, lst in enumerate(lists): if lst: heapq.heappush(heap, (lst.val, i, lst)) while heap: val, i, node = heapq.heappop(heap) tail.next = node tail = tail.next if node.next: heapq.heappush(heap, (node.next.val, i, node.next)) return dummy.next def list_to_linked_list(lst): dummy_head = ListNode(0) current = dummy_head for val in lst: current.next = ListNode(val) current = current.next return dummy_head.next def linked_list_to_list(head): lst = [] current = head while current: lst.append(current.val) current = current.next return lst def run_tests(): test_cases = [ ([[1, 4, 5], [1, 3, 4], [2, 6]], [1, 1, 2, 3, 4, 4, 5, 6]), ([], []), ([[]], []), ] test_results = [] correct_tests = 0 for lists, expected in test_cases: linked_lists = [list_to_linked_list(l) for l in lists] merged_list = mergeKLists(linked_lists) result_list = linked_list_to_list(merged_list) test_result = result_list == expected test_results.append(test_result) if(test_result): correct_tests+=1 print(test_result) print(f"{correct_tests}/{len(test_cases)}") run_tests() | G181: True_x000D_ True_x000D_ True_x000D_ 3/3 | H181: 3 | I181: 0 | J181: 0.11 | K181: 2.03 | L181: loops: 5, conditionals: 3 | M181: =H181+I181 -> 0 | N181: =IF(M181>0,H181/M181,"") -> 0 | O181: =VALUE(TRIM(MID(L181,FIND(":",L181)+1,FIND(",",L181)-FIND(":",L181)-1)))+VALUE(TRIM(MID(L181,FIND("conditionals:",L181)+13,LEN(L181)))) -> 0

Sheet Comparisons
A1: Model | B1: Temperature | C1: top_p | D1: top_k | E1: Avg Accuracy | F1: Avg Time (s) | G1: Avg Memory (MB) | H1: Avg Complexity | I1: Config Label | J1: Rank Accuracy | K1: Rank Time | L1: Rank Memory | M1: Rank Complexity | N1: Composite Rank | O1: Global Best Composite? | P1: Best per Model Composite?
A2: gemini-2.0-flash-lite | B2: 0 | C2: 0.1 | D2: 10 | E2: =AVERAGEIFS('Raw Data'!$N:$N,'Raw Data'!$B:$B,"gemini-2.0-flash-lite",'Raw Data'!$C:$C,"0.0",'Raw Data'!$D:$D,"0.1",'Raw Data'!$E:$E,"10") -> 0 | F2: =AVERAGEIFS('Raw Data'!$J:$J,'Raw Data'!$B:$B,"gemini-2.0-flash-lite",'Raw Data'!$C:$C,"0.0",'Raw Data'!$D:$D,"0.1",'Raw Data'!$E:$E,"10") -> 0 | G2: =AVERAGEIFS('Raw Data'!$K:$K,'Raw Data'!$B:$B,"gemini-2.0-flash-lite",'Raw Data'!$C:$C,"0.0",'Raw Data'!$D:$D,"0.1",'Raw Data'!$E:$E,"10") -> 0 | H2: =AVERAGEIFS('Raw Data'!$O:$O,'Raw Data'!$B:$B,"gemini-2.0-flash-lite",'Raw Data'!$C:$C,"0.0",'Raw Data'!$D:$D,"0.1",'Raw Data'!$E:$E,"10") -> 0 | I2: =A2 & " (T:" & B2 & ", p:" & C2 & ", k:" & D2 & ")" -> 0 | J2: =RANK.EQ(E2,$E$2:$E$37,0) -> 0 | K2: =RANK.EQ(F2,$F$2:$F$37,1) -> 0 | L2: =RANK.EQ(G2,$G$2:$G$37,1) -> 0 | M2: =RANK.EQ(H2,$H$2:$H$37,1) -> 0 | N2: =AVERAGE(J2,K2,L2,M2) -> 0 | O2: =IF(N2=MIN($N$2:$N$37),"Yes","") -> 0 | P2: =IF(N2=MINIFS($N$2:$N$37,$A$2:$A$37,A2),"Yes","") -> 0
A7: gemini-2.0-flash-lite | B7: 0 | C7: 0.5 | D7: 30 | E7: =AVERAGEIFS('Raw Data'!$N:$N,'Raw Data'!$B:$B,"gemini-2.0-flash-lite",'Raw Data'!$C:$C,"0.0",'Raw Data'!$D:$D,"0.5",'Raw Data'!$E:$E,"30") -> 0 | F7: =AVERAGEIFS('Raw Data'!$J:$J,'Raw Data'!$B:$B,"gemini-2.0-flash-lite",'Raw Data'!$C:$C,"0.0",'Raw Data'!$D:$D,"0.5",'Raw Data'!$E:$E,"30") -> 0 | G7: =AVERAGEIFS('Raw Data'!$K:$K,'Raw Data'!$B:$B,"gemini-2.0-flash-lite",'Raw Data'!$C:$C,"0.0",'Raw Data'!$D:$D,"0.5",'Raw Data'!$E:$E,"30") -> 0 | H7: =AVERAGEIFS('Raw Data'!$O:$O,'Raw Data'!$B:$B,"gemini-2.0-flash-lite",'Raw Data'!$C:$C,"0.0",'Raw Data'!$D:$D,"0.5",'Raw Data'!$E:$E,"30") -> 0 | I7: =A7 & " (T:" & B7 & ", p:" & C7 & ", k:" & D7 & ")" -> 0 | J7: =RANK.EQ(E7,$E$2:$E$37,0) -> 0 | K7: =RANK.EQ(F7,$F$2:$F$37,1) -> 0 | L7: =RANK.EQ(G7,$G$2:$G$37,1) -> 0 | M7: =RANK.EQ(H7,$H$2:$H$37,1) -> 0 | N7: =AVERAGE(J7,K7,L7,M7) -> 0 | O7: =IF(N7=MIN($N$2:$N$37),"Yes","") -> 0 | P7: =IF(N7=MINIFS($N$2:$N$37,$A$2:$A$37,A7),"Yes","") -> 0
A12: gemini-2.0-flash-lite | B12: 0 | C12: 0.95 | D12: 100 | E12: =AVERAGEIFS('Raw Data'!$N:$N,'Raw Data'!$B:$B,"gemini-2.0-flash-lite",'Raw Data'!$C:$C,"0.0",'Raw Data'!$D:$D,"0.95",'Raw Data'!$E:$E,"100") -> 0 | F12: =AVERAGEIFS('Raw Data'!$J:$J,'Raw Data'!$B:$B,"gemini-2.0-flash-lite",'Raw Data'!$C:$C,"0.0",'Raw Data'!$D:$D,"0.95",'Raw Data'!$E:$E,"100") -> 0 | G12: =AVERAGEIFS('Raw Data'!$K:$K,'Raw Data'!$B:$B,"gemini-2.0-flash-lite",'Raw Data'!$C:$C,"0.0",'Raw Data'!$D:$D,"0.95",'Raw Data'!$E:$E,"100") -> 0 | H12: =AVERAGEIFS('Raw Data'!$O:$O,'Raw Data'!$B:$B,"gemini-2.0-flash-lite",'Raw Data'!$C:$C,"0.0",'Raw Data'!$D:$D,"0.95",'Raw Data'!$E:$E,"100") -> 0 | I12: =A12 & " (T:" & B12 & ", p:" & C12 & ", k:" & D12 & ")" -> 0 | J12: =RANK.EQ(E12,$E$2:$E$37,0) -> 0 | K12: =RANK.EQ(F12,$F$2:$F$37,1) -> 0 | L12: =RANK.EQ(G12,$G$2:$G$37,1) -> 0 | M12: =RANK.EQ(H12,$H$2:$H$37,1) -> 0 | N12: =AVERAGE(J12,K12,L12,M12) -> 0 | O12: =IF(N12=MIN($N$2:$N$37),"Yes","") -> 0 | P12: =IF(N12=MINIFS($N$2:$N$37,$A$2:$A$37,A12),"Yes","") -> 0
A17: gemini-2.0-flash-lite | B17: 0.5 | C17: 0.1 | D17: 10 | E17: =AVERAGEIFS('Raw Data'!$N:$N,'Raw Data'!$B:$B,"gemini-2.0-flash-lite",'Raw Data'!$C:$C,"0.5",'Raw Data'!$D:$D,"0.1",'Raw Data'!$E:$E,"10") -> 0 | F17: =AVERAGEIFS('Raw Data'!$J:$J,'Raw Data'!$B:$B,"gemini-2.0-flash-lite",'Raw Data'!$C:$C,"0.5",'Raw Data'!$D:$D,"0.1",'Raw Data'!$E:$E,"10") -> 0 | G17: =AVERAGEIFS('Raw Data'!$K:$K,'Raw Data'!$B:$B,"gemini-2.0-flash-lite",'Raw Data'!$C:$C,"0.5",'Raw Data'!$D:$D,"0.1",'Raw Data'!$E:$E,"10") -> 0 | H17: =AVERAGEIFS('Raw Data'!$O:$O,'Raw Data'!$B:$B,"gemini-2.0-flash-lite",'Raw Data'!$C:$C,"0.5",'Raw Data'!$D:$D,"0.1",'Raw Data'!$E:$E,"10") -> 0 | I17: =A17 & " (T:" & B17 & ", p:" & C17 & ", k:" & D17 & ")" -> 0 | J17: =RANK.EQ(E17,$E$2:$E$37,0) -> 0 | K17: =RANK.EQ(F17,$F$2:$F$37,1) -> 0 | L17: =RANK.EQ(G17,$G$2:$G$37,1) -> 0 | M17: =RANK.EQ(H17,$H$2:$H$37,1) -> 0 | N17: =AVERAGE(J17,K17,L17,M17) -> 0 | O17: =IF(N17=MIN($N$2:$N$37),"Yes","") -> 0 | P17: =IF(N17=MINIFS($N$2:$N$37,$A$2:$A$37,A17),"Yes","") -> 0
A22: gemini-2.0-flash-lite | B22: 0.5 | C22: 0.5 | D22: 30 | E22: =AVERAGEIFS('Raw Data'!$N:$N,'Raw Data'!$B:$B,"gemini-2.0-flash-lite",'Raw Data'!$C:$C,"0.5",'Raw Data'!$D:$D,"0.5",'Raw Data'!$E:$E,"30") -> 0 | F22: =AVERAGEIFS('Raw Data'!$J:$J,'Raw Data'!$B:$B,"gemini-2.0-flash-lite",'Raw Data'!$C:$C,"0.5",'Raw Data'!$D:$D,"0.5",'Raw Data'!$E:$E,"30") -> 0 | G22: =AVERAGEIFS('Raw Data'!$K:$K,'Raw Data'!$B:$B,"gemini-2.0-flash-lite",'Raw Data'!$C:$C,"0.5",'Raw Data'!$D:$D,"0.5",'Raw Data'!$E:$E,"30") -> 0 | H22: =AVERAGEIFS('Raw Data'!$O:$O,'Raw Data'!$B:$B,"gemini-2.0-flash-lite",'Raw Data'!$C:$C,"0.5",'Raw Data'!$D:$D,"0.5",'Raw Data'!$E:$E,"30") -> 0 | I22: =A22 & " (T:" & B22 & ", p:" & C22 & ", k:" & D22 & ")" -> 0 | J22: =RANK.EQ(E22,$E$2:$E$37,0) -> 0 | K22: =RANK.EQ(F22,$F$2:$F$37,1) -> 0 | L22: =RANK.EQ(G22,$G$2:$G$37,1) -> 0 | M22: =RANK.EQ(H22,$H$2:$H$37,1) -> 0 | N22: =AVERAGE(J22,K22,L22,M22) -> 0 | O22: =IF(N22=MIN($N$2:$N$37),"Yes","") -> 0 | P22: =IF(N22=MINIFS($N$2:$N$37,$A$2:$A$37,A22),"Yes","") -> 0
A27: gemini-2.0-flash-lite | B27: 0.5 | C27: 0.95 | D27: 100 | E27: =AVERAGEIFS('Raw Data'!$N:$N,'Raw Data'!$B:$B,"gemini-2.0-flash-lite",'Raw Data'!$C:$C,"0.5",'Raw Data'!$D:$D,"0.95",'Raw Data'!$E:$E,"100") -> 0 | F27: =AVERAGEIFS('Raw Data'!$J:$J,'Raw Data'!$B:$B,"gemini-2.0-flash-lite",'Raw Data'!$C:$C,"0.5",'Raw Data'!$D:$D,"0.95",'Raw Data'!$E:$E,"100") -> 0 | G27: =AVERAGEIFS('Raw Data'!$K:$K,'Raw Data'!$B:$B,"gemini-2.0-flash-lite",'Raw Data'!$C:$C,"0.5",'Raw Data'!$D:$D,"0.95",'Raw Data'!$E:$E,"100") -> 0 | H27: =AVERAGEIFS('Raw Data'!$O:$O,'Raw Data'!$B:$B,"gemini-2.0-flash-lite",'Raw Data'!$C:$C,"0.5",'Raw Data'!$D:$D,"0.95",'Raw Data'!$E:$E,"100") -> 0 | I27: =A27 & " (T:" & B27 & ", p:" & C27 & ", k:" & D27 & ")" -> 0 | J27: =RANK.EQ(E27,$E$2:$E$37,0) -> 0 | K27: =RANK.EQ(F27,$F$2:$F$37,1) -> 0 | L27: =RANK.EQ(G27,$G$2:$G$37,1) -> 0 | M27: =RANK.EQ(H27,$H$2:$H$37,1) -> 0 | N27: =AVERAGE(J27,K27,L27,M27) -> 0 | O27: =IF(N27=MIN($N$2:$N$37),"Yes","") -> 0 | P27: =IF(N27=MINIFS($N$2:$N$37,$A$2:$A$37,A27),"Yes","") -> 0
A32: gemini-2.0-flash-lite | B32: 1 | C32: 0.1 | D32: 10 | E32: =AVERAGEIFS('Raw Data'!$N:$N,'Raw Data'!$B:$B,"gemini-2.0-flash-lite",'Raw Data'!$C:$C,"1.0",'Raw Data'!$D:$D,"0.1",'Raw Data'!$E:$E,"10") -> 0 | F32: =AVERAGEIFS('Raw Data'!$J:$J,'Raw Data'!$B:$B,"gemini-2.0-flash-lite",'Raw Data'!$C:$C,"1.0",'Raw Data'!$D:$D,"0.1",'Raw Data'!$E:$E,"10") -> 0 | G32: =AVERAGEIFS('Raw Data'!$K:$K,'Raw Data'!$B:$B,"gemini-2.0-flash-lite",'Raw Data'!$C:$C,"1.0",'Raw Data'!$D:$D,"0.1",'Raw Data'!$E:$E,"10") -> 0 | H32: =AVERAGEIFS('Raw Data'!$O:$O,'Raw Data'!$B:$B,"gemini-2.0-flash-lite",'Raw Data'!$C:$C,"1.0",'Raw Data'!$D:$D,"0.1",'Raw Data'!$E:$E,"10") -> 0 | I32: =A32 & " (T:" & B32 & ", p:" & C32 & ", k:" & D32 & ")" -> 0 | J32: =RANK.EQ(E32,$E$2:$E$37,0) -> 0 | K32: =RANK.EQ(F32,$F$2:$F$37,1) -> 0 | L32: =RANK.EQ(G32,$G$2:$G$37,1) -> 0 | M32: =RANK.EQ(H32,$H$2:$H$37,1) -> 0 | N32: =AVERAGE(J32,K32,L32,M32) -> 0 | O32: =IF(N32=MIN($N$2:$N$37),"Yes","") -> 0 | P32: =IF(N32=MINIFS($N$2:$N$37,$A$2:$A$37,A32),"Yes","") -> 0
A37: gemini-2.0-flash-lite | B37: 1 | C37: 0.5 | D37: 30 | E37: =AVERAGEIFS('Raw Data'!$N:$N,'Raw Data'!$B:$B,"gemini-2.0-flash-lite",'Raw Data'!$C:$C,"1.0",'Raw Data'!$D:$D,"0.5",'Raw Data'!$E:$E,"30") -> 0 | F37: =AVERAGEIFS('Raw Data'!$J:$J,'Raw Data'!$B:$B,"gemini-2.0-flash-lite",'Raw Data'!$C:$C,"1.0",'Raw Data'!$D:$D,"0.5",'Raw Data'!$E:$E,"30") -> 0 | G37: =AVERAGEIFS('Raw Data'!$K:$K,'Raw Data'!$B:$B,"gemini-2.0-flash-lite",'Raw Data'!$C:$C,"1.0",'Raw Data'!$D:$D,"0.5",'Raw Data'!$E:$E,"30") -> 0 | H37: =AVERAGEIFS('Raw Data'!$O:$O,'Raw Data'!$B:$B,"gemini-2.0-flash-lite",'Raw Data'!$C:$C,"1.0",'Raw Data'!$D:$D,"0.5",'Raw Data'!$E:$E,"30") -> 0 | I37: =A37 & " (T:" & B37 & ", p:" & C37 & ", k:" & D37 & ")" -> 0 | J37: =RANK.EQ(E37,$E$2:$E$37,0) -> 0 | K37: =RANK.EQ(F37,$F$2:$F$37,1) -> 0 | L37: =RANK.EQ(G37,$G$2:$G$37,1) -> 0 | M37: =RANK.EQ(H37,$H$2:$H$37,1) -> 0 | N37: =AVERAGE(J37,K37,L37,M37) -> 0 | O37: =IF(N37=MIN($N$2:$N$37),"Yes","") -> 0 | P37: =IF(N37=MINIFS($N$2:$N$37,$A$2:$A$37,A37),"Yes","") -> 0
A42: gemini-2.0-flash-lite | B42: 1 | C42: 0.95 | D42: 100 | E42: =AVERAGEIFS('Raw Data'!$N:$N,'Raw Data'!$B:$B,"gemini-2.0-flash-lite",'Raw Data'!$C:$C,"1.0",'Raw Data'!$D:$D,"0.95",'Raw Data'!$E:$E,"100") -> 0 | F42: =AVERAGEIFS('Raw Data'!$J:$J,'Raw Data'!$B:$B,"gemini-2.0-flash-lite",'Raw Data'!$C:$C,"1.0",'Raw Data'!$D:$D,"0.95",'Raw Data'!$E:$E,"100") -> 0 | G42: =AVERAGEIFS('Raw Data'!$K:$K,'Raw Data'!$B:$B,"gemini-2.0-flash-lite",'Raw Data'!$C:$C,"1.0",'Raw Data'!$D:$D,"0.95",'Raw Data'!$E:$E,"100") -> 0 | H42: =AVERAGEIFS('Raw Data'!$O:$O,'Raw Data'!$B:$B,"gemini-2.0-flash-lite",'Raw Data'!$C:$C,"1.0",'Raw Data'!$D:$D,"0.95",'Raw Data'!$E:$E,"100") -> 0 | I42: =A42 & " (T:" & B42 & ", p:" & C42 & ", k:" & D42 & ")" -> 0 | J42: =RANK.EQ(E42,$E$2:$E$37,0) -> 0 | K42: =RANK.EQ(F42,$F$2:$F$37,1) -> 0 | L42: =RANK.EQ(G42,$G$2:$G$37,1) -> 0 | M42: =RANK.EQ(H42,$H$2:$H$37,1) -> 0 | N42: =AVERAGE(J42,K42,L42,M42) -> 0 | O42: =IF(N42=MIN($N$2:$N$37),"Yes","") -> 0 | P42: =IF(N42=MINIFS($N$2:$N$37,$A$2:$A$37,A42),"Yes","") -> 0
A47: gemini-2.0-flash-lite | B47: 2 | C47: 0.1 | D47: 10 | E47: =AVERAGEIFS('Raw Data'!$N:$N,'Raw Data'!$B:$B,"gemini-2.0-flash-lite",'Raw Data'!$C:$C,"2.0",'Raw Data'!$D:$D,"0.1",'Raw Data'!$E:$E,"10") -> 0 | F47: =AVERAGEIFS('Raw Data'!$J:$J,'Raw Data'!$B:$B,"gemini-2.0-flash-lite",'Raw Data'!$C:$C,"2.0",'Raw Data'!$D:$D,"0.1",'Raw Data'!$E:$E,"10") -> 0 | G47: =AVERAGEIFS('Raw Data'!$K:$K,'Raw Data'!$B:$B,"gemini-2.0-flash-lite",'Raw Data'!$C:$C,"2.0",'Raw Data'!$D:$D,"0.1",'Raw Data'!$E:$E,"10") -> 0 | H47: =AVERAGEIFS('Raw Data'!$O:$O,'Raw Data'!$B:$B,"gemini-2.0-flash-lite",'Raw Data'!$C:$C,"2.0",'Raw Data'!$D:$D,"0.1",'Raw Data'!$E:$E,"10") -> 0 | I47: =A47 & " (T:" & B47 & ", p:" & C47 & ", k:" & D47 & ")" -> 0 | J47: =RANK.EQ(E47,$E$2:$E$37,0) -> 0 | K47: =RANK.EQ(F47,$F$2:$F$37,1) -> 0 | L47: =RANK.EQ(G47,$G$2:$G$37,1) -> 0 | M47: =RANK.EQ(H47,$H$2:$H$37,1) -> 0 | N47: =AVERAGE(J47,K47,L47,M47) -> 0 | O47: =IF(N47=MIN($N$2:$N$37),"Yes","") -> 0 | P47: =IF(N47=MINIFS($N$2:$N$37,$A$2:$A$37,A47),"Yes","") -> 0
A52: gemini-2.0-flash-lite | B52: 2 | C52: 0.5 | D52: 30 | E52: =AVERAGEIFS('Raw Data'!$N:$N,'Raw Data'!$B:$B,"gemini-2.0-flash-lite",'Raw Data'!$C:$C,"2.0",'Raw Data'!$D:$D,"0.5",'Raw Data'!$E:$E,"30") -> 0 | F52: =AVERAGEIFS('Raw Data'!$J:$J,'Raw Data'!$B:$B,"gemini-2.0-flash-lite",'Raw Data'!$C:$C,"2.0",'Raw Data'!$D:$D,"0.5",'Raw Data'!$E:$E,"30") -> 0 | G52: =AVERAGEIFS('Raw Data'!$K:$K,'Raw Data'!$B:$B,"gemini-2.0-flash-lite",'Raw Data'!$C:$C,"2.0",'Raw Data'!$D:$D,"0.5",'Raw Data'!$E:$E,"30") -> 0 | H52: =AVERAGEIFS('Raw Data'!$O:$O,'Raw Data'!$B:$B,"gemini-2.0-flash-lite",'Raw Data'!$C:$C,"2.0",'Raw Data'!$D:$D,"0.5",'Raw Data'!$E:$E,"30") -> 0 | I52: =A52 & " (T:" & B52 & ", p:" & C52 & ", k:" & D52 & ")" -> 0 | J52: =RANK.EQ(E52,$E$2:$E$37,0) -> 0 | K52: =RANK.EQ(F52,$F$2:$F$37,1) -> 0 | L52: =RANK.EQ(G52,$G$2:$G$37,1) -> 0 | M52: =RANK.EQ(H52,$H$2:$H$37,1) -> 0 | N52: =AVERAGE(J52,K52,L52,M52) -> 0 | O52: =IF(N52=MIN($N$2:$N$37),"Yes","") -> 0 | P52: =IF(N52=MINIFS($N$2:$N$37,$A$2:$A$37,A52),"Yes","") -> 0
A57: gemini-2.0-flash-lite | B57: 2 | C57: 0.95 | D57: 100 | E57: =AVERAGEIFS('Raw Data'!$N:$N,'Raw Data'!$B:$B,"gemini-2.0-flash-lite",'Raw Data'!$C:$C,"2.0",'Raw Data'!$D:$D,"0.95",'Raw Data'!$E:$E,"100") -> 0 | F57: =AVERAGEIFS('Raw Data'!$J:$J,'Raw Data'!$B:$B,"gemini-2.0-flash-lite",'Raw Data'!$C:$C,"2.0",'Raw Data'!$D:$D,"0.95",'Raw Data'!$E:$E,"100") -> 0 | G57: =AVERAGEIFS('Raw Data'!$K:$K,'Raw Data'!$B:$B,"gemini-2.0-flash-lite",'Raw Data'!$C:$C,"2.0",'Raw Data'!$D:$D,"0.95",'Raw Data'!$E:$E,"100") -> 0 | H57: =AVERAGEIFS('Raw Data'!$O:$O,'Raw Data'!$B:$B,"gemini-2.0-flash-lite",'Raw Data'!$C:$C,"2.0",'Raw Data'!$D:$D,"0.95",'Raw Data'!$E:$E,"100") -> 0 | I57: =A57 & " (T:" & B57 & ", p:" & C57 & ", k:" & D57 & ")" -> 0 | J57: =RANK.EQ(E57,$E$2:$E$37,0) -> 0 | K57: =RANK.EQ(F57,$F$2:$F$37,1) -> 0 | L57: =RANK.EQ(G57,$G$2:$G$37,1) -> 0 | M57: =RANK.EQ(H57,$H$2:$H$37,1) -> 0 | N57: =AVERAGE(J57,K57,L57,M57) -> 0 | O57: =IF(N57=MIN($N$2:$N$37),"Yes","") -> 0 | P57: =IF(N57=MINIFS($N$2:$N$37,$A$2:$A$37,A57),"Yes","") -> 0
A62: gemini-2.0-flash | B62: 0 | C62: 0.1 | D62: 10 | E62: =AVERAGEIFS('Raw Data'!$N:$N,'Raw Data'!$B:$B,"gemini-2.0-flash",'Raw Data'!$C:$C,"0.0",'Raw Data'!$D:$D,"0.1",'Raw Data'!$E:$E,"10") -> 0 | F62: =AVERAGEIFS('Raw Data'!$J:$J,'Raw Data'!$B:$B,"gemini-2.0-flash",'Raw Data'!$C:$C,"0.0",'Raw Data'!$D:$D,"0.1",'Raw Data'!$E:$E,"10") -> 0 | G62: =AVERAGEIFS('Raw Data'!$K:$K,'Raw Data'!$B:$B,"gemini-2.0-flash",'Raw Data'!$C:$C,"0.0",'Raw Data'!$D:$D,"0.1",'Raw Data'!$E:$E,"10") -> 0 | H62: =AVERAGEIFS('Raw Data'!$O:$O,'Raw Data'!$B:$B,"gemini-2.0-flash",'Raw Data'!$C:$C,"0.0",'Raw Data'!$D:$D,"0.1",'Raw Data'!$E:$E,"10") -> 0 | I62: =A62 & " (T:" & B62 & ", p:" & C62 & ", k:" & D62 & ")" -> 0 | J62: =RANK.EQ(E62,$E$2:$E$37,0) -> 0 | K62: =RANK.EQ(F62,$F$2:$F$37,1) -> 0 | L62: =RANK.EQ(G62,$G$2:$G$37,1) -> 0 | M62: =RANK.EQ(H62,$H$2:$H$37,1) -> 0 | N62: =AVERAGE(J62,K62,L62,M62) -> 0 | O62: =IF(N62=MIN($N$2:$N$37),"Yes","") -> 0 | P62: =IF(N62=MINIFS($N$2:$N$37,$A$2:$A$37,A62),"Yes","") -> 0
A67: gemini-2.0-flash | B67: 0 | C67: 0.5 | D67: 30 | E67: =AVERAGEIFS('Raw Data'!$N:$N,'Raw Data'!$B:$B,"gemini-2.0-flash",'Raw Data'!$C:$C,"0.0",'Raw Data'!$D:$D,"0.5",'Raw Data'!$E:$E,"30") -> 0 | F67: =AVERAGEIFS('Raw Data'!$J:$J,'Raw Data'!$B:$B,"gemini-2.0-flash",'Raw Data'!$C:$C,"0.0",'Raw Data'!$D:$D,"0.5",'Raw Data'!$E:$E,"30") -> 0 | G67: =AVERAGEIFS('Raw Data'!$K:$K,'Raw Data'!$B:$B,"gemini-2.0-flash",'Raw Data'!$C:$C,"0.0",'Raw Data'!$D:$D,"0.5",'Raw Data'!$E:$E,"30") -> 0 | H67: =AVERAGEIFS('Raw Data'!$O:$O,'Raw Data'!$B:$B,"gemini-2.0-flash",'Raw Data'!$C:$C,"0.0",'Raw Data'!$D:$D,"0.5",'Raw Data'!$E:$E,"30") -> 0 | I67: =A67 & " (T:" & B67 & ", p:" & C67 & ", k:" & D67 & ")" -> 0 | J67: =RANK.EQ(E67,$E$2:$E$37,0) -> 0 | K67: =RANK.EQ(F67,$F$2:$F$37,1) -> 0 | L67: =RANK.EQ(G67,$G$2:$G$37,1) -> 0 | M67: =RANK.EQ(H67,$H$2:$H$37,1) -> 0 | N67: =AVERAGE(J67,K67,L67,M67) -> 0 | O67: =IF(N67=MIN($N$2:$N$37),"Yes","") -> 0 | P67: =IF(N67=MINIFS($N$2:$N$37,$A$2:$A$37,A67),"Yes","") -> 0
A72: gemini-2.0-flash | B72: 0 | C72: 0.95 | D72: 100 | E72: =AVERAGEIFS('Raw Data'!$N:$N,'Raw Data'!$B:$B,"gemini-2.0-flash",'Raw Data'!$C:$C,"0.0",'Raw Data'!$D:$D,"0.95",'Raw Data'!$E:$E,"100") -> 0 | F72: =AVERAGEIFS('Raw Data'!$J:$J,'Raw Data'!$B:$B,"gemini-2.0-flash",'Raw Data'!$C:$C,"0.0",'Raw Data'!$D:$D,"0.95",'Raw Data'!$E:$E,"100") -> 0 | G72: =AVERAGEIFS('Raw Data'!$K:$K,'Raw Data'!$B:$B,"gemini-2.0-flash",'Raw Data'!$C:$C,"0.0",'Raw Data'!$D:$D,"0.95",'Raw Data'!$E:$E,"100") -> 0 | H72: =AVERAGEIFS('Raw Data'!$O:$O,'Raw Data'!$B:$B,"gemini-2.0-flash",'Raw Data'!$C:$C,"0.0",'Raw Data'!$D:$D,"0.95",'Raw Data'!$E:$E,"100") -> 0 | I72: =A72 & " (T:" & B72 & ", p:" & C72 & ", k:" & D72 & ")" -> 0 | J72: =RANK.EQ(E72,$E$2:$E$37,0) -> 0 | K72: =RANK.EQ(F72,$F$2:$F$37,1) -> 0 | L72: =RANK.EQ(G72,$G$2:$G$37,1) -> 0 | M72: =RANK.EQ(H72,$H$2:$H$37,1) -> 0 | N72: =AVERAGE(J72,K72,L72,M72) -> 0 | O72: =IF(N72=MIN($N$2:$N$37),"Yes","") -> 0 | P72: =IF(N72=MINIFS($N$2:$N$37,$A$2:$A$37,A72),"Yes","") -> 0
A77: gemini-2.0-flash | B77: 0.5 | C77: 0.1 | D77: 10 | E77: =AVERAGEIFS('Raw Data'!$N:$N,'Raw Data'!$B:$B,"gemini-2.0-flash",'Raw Data'!$C:$C,"0.5",'Raw Data'!$D:$D,"0.1",'Raw Data'!$E:$E,"10") -> 0 | F77: =AVERAGEIFS('Raw Data'!$J:$J,'Raw Data'!$B:$B,"gemini-2.0-flash",'Raw Data'!$C:$C,"0.5",'Raw Data'!$D:$D,"0.1",'Raw Data'!$E:$E,"10") -> 0 | G77: =AVERAGEIFS('Raw Data'!$K:$K,'Raw Data'!$B:$B,"gemini-2.0-flash",'Raw Data'!$C:$C,"0.5",'Raw Data'!$D:$D,"0.1",'Raw Data'!$E:$E,"10") -> 0 | H77: =AVERAGEIFS('Raw Data'!$O:$O,'Raw Data'!$B:$B,"gemini-2.0-flash",'Raw Data'!$C:$C,"0.5",'Raw Data'!$D:$D,"0.1",'Raw Data'!$E:$E,"10") -> 0 | I77: =A77 & " (T:" & B77 & ", p:" & C77 & ", k:" & D77 & ")" -> 0 | J77: =RANK.EQ(E77,$E$2:$E$37,0) -> 0 | K77: =RANK.EQ(F77,$F$2:$F$37,1) -> 0 | L77: =RANK.EQ(G77,$G$2:$G$37,1) -> 0 | M77: =RANK.EQ(H77,$H$2:$H$37,1) -> 0 | N77: =AVERAGE(J77,K77,L77,M77) -> 0 | O77: =IF(N77=MIN($N$2:$N$37),"Yes","") -> 0 | P77: =IF(N77=MINIFS($N$2:$N$37,$A$2:$A$37,A77),"Yes","") -> 0
A82: gemini-2.0-flash | B82: 0.5 | C82: 0.5 | D82: 30 | E82: =AVERAGEIFS('Raw Data'!$N:$N,'Raw Data'!$B:$B,"gemini-2.0-flash",'Raw Data'!$C:$C,"0.5",'Raw Data'!$D:$D,"0.5",'Raw Data'!$E:$E,"30") -> 0 | F82: =AVERAGEIFS('Raw Data'!$J:$J,'Raw Data'!$B:$B,"gemini-2.0-flash",'Raw Data'!$C:$C,"0.5",'Raw Data'!$D:$D,"0.5",'Raw Data'!$E:$E,"30") -> 0 | G82: =AVERAGEIFS('Raw Data'!$K:$K,'Raw Data'!$B:$B,"gemini-2.0-flash",'Raw Data'!$C:$C,"0.5",'Raw Data'!$D:$D,"0.5",'Raw Data'!$E:$E,"30") -> 0 | H82: =AVERAGEIFS('Raw Data'!$O:$O,'Raw Data'!$B:$B,"gemini-2.0-flash",'Raw Data'!$C:$C,"0.5",'Raw Data'!$D:$D,"0.5",'Raw Data'!$E:$E,"30") -> 0 | I82: =A82 & " (T:" & B82 & ", p:" & C82 & ", k:" & D82 & ")" -> 0 | J82: =RANK.EQ(E82,$E$2:$E$37,0) -> 0 | K82: =RANK.EQ(F82,$F$2:$F$37,1) -> 0 | L82: =RANK.EQ(G82,$G$2:$G$37,1) -> 0 | M82: =RANK.EQ(H82,$H$2:$H$37,1) -> 0 | N82: =AVERAGE(J82,K82,L82,M82) -> 0 | O82: =IF(N82=MIN($N$2:$N$37),"Yes","") -> 0 | P82: =IF(N82=MINIFS($N$2:$N$37,$A$2:$A$37,A82),"Yes","") -> 0
A87: gemini-2.0-flash | B87: 0.5 | C87: 0.95 | D87: 100 | E87: =AVERAGEIFS('Raw Data'!$N:$N,'Raw Data'!$B:$B,"gemini-2.0-flash",'Raw Data'!$C:$C,"0.5",'Raw Data'!$D:$D,"0.95",'Raw Data'!$E:$E,"100") -> 0 | F87: =AVERAGEIFS('Raw Data'!$J:$J,'Raw Data'!$B:$B,"gemini-2.0-flash",'Raw Data'!$C:$C,"0.5",'Raw Data'!$D:$D,"0.95",'Raw Data'!$E:$E,"100") -> 0 | G87: =AVERAGEIFS('Raw Data'!$K:$K,'Raw Data'!$B:$B,"gemini-2.0-flash",'Raw Data'!$C:$C,"0.5",'Raw Data'!$D:$D,"0.95",'Raw Data'!$E:$E,"100") -> 0 | H87: =AVERAGEIFS('Raw Data'!$O:$O,'Raw Data'!$B:$B,"gemini-2.0-flash",'Raw Data'!$C:$C,"0.5",'Raw Data'!$D:$D,"0.95",'Raw Data'!$E:$E,"100") -> 0 | I87: =A87 & " (T:" & B87 & ", p:" & C87 & ", k:" & D87 & ")" -> 0 | J87: =RANK.EQ(E87,$E$2:$E$37,0) -> 0 | K87: =RANK.EQ(F87,$F$2:$F$37,1) -> 0 | L87: =RANK.EQ(G87,$G$2:$G$37,1) -> 0 | M87: =RANK.EQ(H87,$H$2:$H$37,1) -> 0 | N87: =AVERAGE(J87,K87,L87,M87) -> 0 | O87: =IF(N87=MIN($N$2:$N$37),"Yes","") -> 0 | P87: =IF(N87=MINIFS($N$2:$N$37,$A$2:$A$37,A87),"Yes","") -> 0
A92: gemini-2.0-flash | B92: 1 | C92: 0.1 | D92: 10 | E92: =AVERAGEIFS('Raw Data'!$N:$N,'Raw Data'!$B:$B,"gemini-2.0-flash",'Raw Data'!$C:$C,"1.0",'Raw Data'!$D:$D,"0.1",'Raw Data'!$E:$E,"10") -> 0 | F92: =AVERAGEIFS('Raw Data'!$J:$J,'Raw Data'!$B:$B,"gemini-2.0-flash",'Raw Data'!$C:$C,"1.0",'Raw Data'!$D:$D,"0.1",'Raw Data'!$E:$E,"10") -> 0 | G92: =AVERAGEIFS('Raw Data'!$K:$K,'Raw Data'!$B:$B,"gemini-2.0-flash",'Raw Data'!$C:$C,"1.0",'Raw Data'!$D:$D,"0.1",'Raw Data'!$E:$E,"10") -> 0 | H92: =AVERAGEIFS('Raw Data'!$O:$O,'Raw Data'!$B:$B,"gemini-2.0-flash",'Raw Data'!$C:$C,"1.0",'Raw Data'!$D:$D,"0.1",'Raw Data'!$E:$E,"10") -> 0 | I92: =A92 & " (T:" & B92 & ", p:" & C92 & ", k:" & D92 & ")" -> 0 | J92: =RANK.EQ(E92,$E$2:$E$37,0) -> 0 | K92: =RANK.EQ(F92,$F$2:$F$37,1) -> 0 | L92: =RANK.EQ(G92,$G$2:$G$37,1) -> 0 | M92: =RANK.EQ(H92,$H$2:$H$37,1) -> 0 | N92: =AVERAGE(J92,K92,L92,M92) -> 0 | O92: =IF(N92=MIN($N$2:$N$37),"Yes","") -> 0 | P92: =IF(N92=MINIFS($N$2:$N$37,$A$2:$A$37,A92),"Yes","") -> 0
A97: gemini-2.0-flash | B97: 1 | C97: 0.5 | D97: 30 | E97: =AVERAGEIFS('Raw Data'!$N:$N,'Raw Data'!$B:$B,"gemini-2.0-flash",'Raw Data'!$C:$C,"1.0",'Raw Data'!$D:$D,"0.5",'Raw Data'!$E:$E,"30") -> 0 | F97: =AVERAGEIFS('Raw Data'!$J:$J,'Raw Data'!$B:$B,"gemini-2.0-flash",'Raw Data'!$C:$C,"1.0",'Raw Data'!$D:$D,"0.5",'Raw Data'!$E:$E,"30") -> 0 | G97: =AVERAGEIFS('Raw Data'!$K:$K,'Raw Data'!$B:$B,"gemini-2.0-flash",'Raw Data'!$C:$C,"1.0",'Raw Data'!$D:$D,"0.5",'Raw Data'!$E:$E,"30") -> 0 | H97: =AVERAGEIFS('Raw Data'!$O:$O,'Raw Data'!$B:$B,"gemini-2.0-flash",'Raw Data'!$C:$C,"1.0",'Raw Data'!$D:$D,"0.5",'Raw Data'!$E:$E,"30") -> 0 | I97: =A97 & " (T:" & B97 & ", p:" & C97 & ", k:" & D97 & ")" -> 0 | J97: =RANK.EQ(E97,$E$2:$E$37,0) -> 0 | K97: =RANK.EQ(F97,$F$2:$F$37,1) -> 0 | L97: =RANK.EQ(G97,$G$2:$G$37,1) -> 0 | M97: =RANK.EQ(H97,$H$2:$H$37,1) -> 0 | N97: =AVERAGE(J97,K97,L97,M97) -> 0 | O97: =IF(N97=MIN($N$2:$N$37),"Yes","") -> 0 | P97: =IF(N97=MINIFS($N$2:$N$37,$A$2:$A$37,A97),"Yes","") -> 0
A102: gemini-2.0-flash | B102: 1 | C102: 0.95 | D102: 100 | E102: =AVERAGEIFS('Raw Data'!$N:$N,'Raw Data'!$B:$B,"gemini-2.0-flash",'Raw Data'!$C:$C,"1.0",'Raw Data'!$D:$D,"0.95",'Raw Data'!$E:$E,"100") -> 0 | F102: =AVERAGEIFS('Raw Data'!$J:$J,'Raw Data'!$B:$B,"gemini-2.0-flash",'Raw Data'!$C:$C,"1.0",'Raw Data'!$D:$D,"0.95",'Raw Data'!$E:$E,"100") -> 0 | G102: =AVERAGEIFS('Raw Data'!$K:$K,'Raw Data'!$B:$B,"gemini-2.0-flash",'Raw Data'!$C:$C,"1.0",'Raw Data'!$D:$D,"0.95",'Raw Data'!$E:$E,"100") -> 0 | H102: =AVERAGEIFS('Raw Data'!$O:$O,'Raw Data'!$B:$B,"gemini-2.0-flash",'Raw Data'!$C:$C,"1.0",'Raw Data'!$D:$D,"0.95",'Raw Data'!$E:$E,"100") -> 0 | I102: =A102 & " (T:" & B102 & ", p:" & C102 & ", k:" & D102 & ")" -> 0 | J102: =RANK.EQ(E102,$E$2:$E$37,0) -> 0 | K102: =RANK.EQ(F102,$F$2:$F$37,1) -> 0 | L102: =RANK.EQ(G102,$G$2:$G$37,1) -> 0 | M102: =RANK.EQ(H102,$H$2:$H$37,1) -> 0 | N102: =AVERAGE(J102,K102,L102,M102) -> 0 | O102: =IF(N102=MIN($N$2:$N$37),"Yes","") -> 0 | P102: =IF(N102=MINIFS($N$2:$N$37,$A$2:$A$37,A102),"Yes","") -> 0
A107: gemini-2.0-flash | B107: 2 | C107: 0.1 | D107: 10 | E107: =AVERAGEIFS('Raw Data'!$N:$N,'Raw Data'!$B:$B,"gemini-2.0-flash",'Raw Data'!$C:$C,"2.0",'Raw Data'!$D:$D,"0.1",'Raw Data'!$E:$E,"10") -> 0 | F107: =AVERAGEIFS('Raw Data'!$J:$J,'Raw Data'!$B:$B,"gemini-2.0-flash",'Raw Data'!$C:$C,"2.0",'Raw Data'!$D:$D,"0.1",'Raw Data'!$E:$E,"10") -> 0 | G107: =AVERAGEIFS('Raw Data'!$K:$K,'Raw Data'!$B:$B,"gemini-2.0-flash",'Raw Data'!$C:$C,"2.0",'Raw Data'!$D:$D,"0.1",'Raw Data'!$E:$E,"10") -> 0 | H107: =AVERAGEIFS('Raw Data'!$O:$O,'Raw Data'!$B:$B,"gemini-2.0-flash",'Raw Data'!$C:$C,"2.0",'Raw Data'!$D:$D,"0.1",'Raw Data'!$E:$E,"10") -> 0 | I107: =A107 & " (T:" & B107 & ", p:" & C107 & ", k:" & D107 & ")" -> 0 | J107: =RANK.EQ(E107,$E$2:$E$37,0) -> 0 | K107: =RANK.EQ(F107,$F$2:$F$37,1) -> 0 | L107: =RANK.EQ(G107,$G$2:$G$37,1) -> 0 | M107: =RANK.EQ(H107,$H$2:$H$37,1) -> 0 | N107: =AVERAGE(J107,K107,L107,M107) -> 0 | O107: =IF(N107=MIN($N$2:$N$37),"Yes","") -> 0 | P107: =IF(N107=MINIFS($N$2:$N$37,$A$2:$A$37,A107),"Yes","") -> 0
A112: gemini-2.0-flash | B112: 2 | C112: 0.5 | D112: 30 | E112: =AVERAGEIFS('Raw Data'!$N:$N,'Raw Data'!$B:$B,"gemini-2.0-flash",'Raw Data'!$C:$C,"2.0",'Raw Data'!$D:$D,"0.5",'Raw Data'!$E:$E,"30") -> 0 | F112: =AVERAGEIFS('Raw Data'!$J:$J,'Raw Data'!$B:$B,"gemini-2.0-flash",'Raw Data'!$C:$C,"2.0",'Raw Data'!$D:$D,"0.5",'Raw Data'!$E:$E,"30") -> 0 | G112: =AVERAGEIFS('Raw Data'!$K:$K,'Raw Data'!$B:$B,"gemini-2.0-flash",'Raw Data'!$C:$C,"2.0",'Raw Data'!$D:$D,"0.5",'Raw Data'!$E:$E,"30") -> 0 | H112: =AVERAGEIFS('Raw Data'!$O:$O,'Raw Data'!$B:$B,"gemini-2.0-flash",'Raw Data'!$C:$C,"2.0",'Raw Data'!$D:$D,"0.5",'Raw Data'!$E:$E,"30") -> 0 | I112: =A112 & " (T:" & B112 & ", p:" & C112 & ", k:" & D112 & ")" -> 0 | J112: =RANK.EQ(E112,$E$2:$E$37,0) -> 0 | K112: =RANK.EQ(F112,$F$2:$F$37,1) -> 0 | L112: =RANK.EQ(G112,$G$2:$G$37,1) -> 0 | M112: =RANK.EQ(H112,$H$2:$H$37,1) -> 0 | N112: =AVERAGE(J112,K112,L112,M112) -> 0 | O112: =IF(N112=MIN($N$2:$N$37),"Yes","") -> 0 | P112: =IF(N112=MINIFS($N$2:$N$37,$A$2:$A$37,A112),"Yes","") -> 0
A117: gemini-2.0-flash | B117: 2 | C117: 0.95 | D117: 100 | E117: =AVERAGEIFS('Raw Data'!$N:$N,'Raw Data'!$B:$B,"gemini-2.0-flash",'Raw Data'!$C:$C,"2.0",'Raw Data'!$D:$D,"0.95",'Raw Data'!$E:$E,"100") -> 0 | F117: =AVERAGEIFS('Raw Data'!$J:$J,'Raw Data'!$B:$B,"gemini-2.0-flash",'Raw Data'!$C:$C,"2.0",'Raw Data'!$D:$D,"0.95",'Raw Data'!$E:$E,"100") -> 0 | G117: =AVERAGEIFS('Raw Data'!$K:$K,'Raw Data'!$B:$B,"gemini-2.0-flash",'Raw Data'!$C:$C,"2.0",'Raw Data'!$D:$D,"0.95",'Raw Data'!$E:$E,"100") -> 0 | H117: =AVERAGEIFS('Raw Data'!$O:$O,'Raw Data'!$B:$B,"gemini-2.0-flash",'Raw Data'!$C:$C,"2.0",'Raw Data'!$D:$D,"0.95",'Raw Data'!$E:$E,"100") -> 0 | I117: =A117 & " (T:" & B117 & ", p:" & C117 & ", k:" & D117 & ")" -> 0 | J117: =RANK.EQ(E117,$E$2:$E$37,0) -> 0 | K117: =RANK.EQ(F117,$F$2:$F$37,1) -> 0 | L117: =RANK.EQ(G117,$G$2:$G$37,1) -> 0 | M117: =RANK.EQ(H117,$H$2:$H$37,1) -> 0 | N117: =AVERAGE(J117,K117,L117,M117) -> 0 | O117: =IF(N117=MIN($N$2:$N$37),"Yes","") -> 0 | P117: =IF(N117=MINIFS($N$2:$N$37,$A$2:$A$37,A117),"Yes","") -> 0
A122: gemini-2.0-pro-exp-02-05 | B122: 0 | C122: 0.1 | D122: 10 | E122: =AVERAGEIFS('Raw Data'!$N:$N,'Raw Data'!$B:$B,"gemini-2.0-pro-exp-02-05",'Raw Data'!$C:$C,"0.0",'Raw Data'!$D:$D,"0.1",'Raw Data'!$E:$E,"10") -> 0 | F122: =AVERAGEIFS('Raw Data'!$J:$J,'Raw Data'!$B:$B,"gemini-2.0-pro-exp-02-05",'Raw Data'!$C:$C,"0.0",'Raw Data'!$D:$D,"0.1",'Raw Data'!$E:$E,"10") -> 0 | G122: =AVERAGEIFS('Raw Data'!$K:$K,'Raw Data'!$B:$B,"gemini-2.0-pro-exp-02-05",'Raw Data'!$C:$C,"0.0",'Raw Data'!$D:$D,"0.1",'Raw Data'!$E:$E,"10") -> 0 | H122: =AVERAGEIFS('Raw Data'!$O:$O,'Raw Data'!$B:$B,"gemini-2.0-pro-exp-02-05",'Raw Data'!$C:$C,"0.0",'Raw Data'!$D:$D,"0.1",'Raw Data'!$E:$E,"10") -> 0 | I122: =A122 & " (T:" & B122 & ", p:" & C122 & ", k:" & D122 & ")" -> 0 | J122: =RANK.EQ(E122,$E$2:$E$37,0) -> 0 | K122: =RANK.EQ(F122,$F$2:$F$37,1) -> 0 | L122: =RANK.EQ(G122,$G$2:$G$37,1) -> 0 | M122: =RANK.EQ(H122,$H$2:$H$37,1) -> 0 | N122: =AVERAGE(J122,K122,L122,M122) -> 0 | O122: =IF(N122=MIN($N$2:$N$37),"Yes","") -> 0 | P122: =IF(N122=MINIFS($N$2:$N$37,$A$2:$A$37,A122),"Yes","") -> 0
A127: gemini-2.0-pro-exp-02-05 | B127: 0 | C127: 0.5 | D127: 30 | E127: =AVERAGEIFS('Raw Data'!$N:$N,'Raw Data'!$B:$B,"gemini-2.0-pro-exp-02-05",'Raw Data'!$C:$C,"0.0",'Raw Data'!$D:$D,"0.5",'Raw Data'!$E:$E,"30") -> 0 | F127: =AVERAGEIFS('Raw Data'!$J:$J,'Raw Data'!$B:$B,"gemini-2.0-pro-exp-02-05",'Raw Data'!$C:$C,"0.0",'Raw Data'!$D:$D,"0.5",'Raw Data'!$E:$E,"30") -> 0 | G127: =AVERAGEIFS('Raw Data'!$K:$K,'Raw Data'!$B:$B,"gemini-2.0-pro-exp-02-05",'Raw Data'!$C:$C,"0.0",'Raw Data'!$D:$D,"0.5",'Raw Data'!$E:$E,"30") -> 0 | H127: =AVERAGEIFS('Raw Data'!$O:$O,'Raw Data'!$B:$B,"gemini-2.0-pro-exp-02-05",'Raw Data'!$C:$C,"0.0",'Raw Data'!$D:$D,"0.5",'Raw Data'!$E:$E,"30") -> 0 | I127: =A127 & " (T:" & B127 & ", p:" & C127 & ", k:" & D127 & ")" -> 0 | J127: =RANK.EQ(E127,$E$2:$E$37,0) -> 0 | K127: =RANK.EQ(F127,$F$2:$F$37,1) -> 0 | L127: =RANK.EQ(G127,$G$2:$G$37,1) -> 0 | M127: =RANK.EQ(H127,$H$2:$H$37,1) -> 0 | N127: =AVERAGE(J127,K127,L127,M127) -> 0 | O127: =IF(N127=MIN($N$2:$N$37),"Yes","") -> 0 | P127: =IF(N127=MINIFS($N$2:$N$37,$A$2:$A$37,A127),"Yes","") -> 0
A132: gemini-2.0-pro-exp-02-05 | B132: 0 | C132: 0.95 | D132: 100 | E132: =AVERAGEIFS('Raw Data'!$N:$N,'Raw Data'!$B:$B,"gemini-2.0-pro-exp-02-05",'Raw Data'!$C:$C,"0.0",'Raw Data'!$D:$D,"0.95",'Raw Data'!$E:$E,"100") -> 0 | F132: =AVERAGEIFS('Raw Data'!$J:$J,'Raw Data'!$B:$B,"gemini-2.0-pro-exp-02-05",'Raw Data'!$C:$C,"0.0",'Raw Data'!$D:$D,"0.95",'Raw Data'!$E:$E,"100") -> 0 | G132: =AVERAGEIFS('Raw Data'!$K:$K,'Raw Data'!$B:$B,"gemini-2.0-pro-exp-02-05",'Raw Data'!$C:$C,"0.0",'Raw Data'!$D:$D,"0.95",'Raw Data'!$E:$E,"100") -> 0 | H132: =AVERAGEIFS('Raw Data'!$O:$O,'Raw Data'!$B:$B,"gemini-2.0-pro-exp-02-05",'Raw Data'!$C:$C,"0.0",'Raw Data'!$D:$D,"0.95",'Raw Data'!$E:$E,"100") -> 0 | I132: =A132 & " (T:" & B132 & ", p:" & C132 & ", k:" & D132 & ")" -> 0 | J132: =RANK.EQ(E132,$E$2:$E$37,0) -> 0 | K132: =RANK.EQ(F132,$F$2:$F$37,1) -> 0 | L132: =RANK.EQ(G132,$G$2:$G$37,1) -> 0 | M132: =RANK.EQ(H132,$H$2:$H$37,1) -> 0 | N132: =AVERAGE(J132,K132,L132,M132) -> 0 | O132: =IF(N132=MIN($N$2:$N$37),"Yes","") -> 0 | P132: =IF(N132=MINIFS($N$2:$N$37,$A$2:$A$37,A132),"Yes","") -> 0
A137: gemini-2.0-pro-exp-02-05 | B137: 0.5 | C137: 0.1 | D137: 10 | E137: =AVERAGEIFS('Raw Data'!$N:$N,'Raw Data'!$B:$B,"gemini-2.0-pro-exp-02-05",'Raw Data'!$C:$C,"0.5",'Raw Data'!$D:$D,"0.1",'Raw Data'!$E:$E,"10") -> 0 | F137: =AVERAGEIFS('Raw Data'!$J:$J,'Raw Data'!$B:$B,"gemini-2.0-pro-exp-02-05",'Raw Data'!$C:$C,"0.5",'Raw Data'!$D:$D,"0.1",'Raw Data'!$E:$E,"10") -> 0 | G137: =AVERAGEIFS('Raw Data'!$K:$K,'Raw Data'!$B:$B,"gemini-2.0-pro-exp-02-05",'Raw Data'!$C:$C,"0.5",'Raw Data'!$D:$D,"0.1",'Raw Data'!$E:$E,"10") -> 0 | H137: =AVERAGEIFS('Raw Data'!$O:$O,'Raw Data'!$B:$B,"gemini-2.0-pro-exp-02-05",'Raw Data'!$C:$C,"0.5",'Raw Data'!$D:$D,"0.1",'Raw Data'!$E:$E,"10") -> 0 | I137: =A137 & " (T:" & B137 & ", p:" & C137 & ", k:" & D137 & ")" -> 0 | J137: =RANK.EQ(E137,$E$2:$E$37,0) -> 0 | K137: =RANK.EQ(F137,$F$2:$F$37,1) -> 0 | L137: =RANK.EQ(G137,$G$2:$G$37,1) -> 0 | M137: =RANK.EQ(H137,$H$2:$H$37,1) -> 0 | N137: =AVERAGE(J137,K137,L137,M137) -> 0 | O137: =IF(N137=MIN($N$2:$N$37),"Yes","") -> 0 | P137: =IF(N137=MINIFS($N$2:$N$37,$A$2:$A$37,A137),"Yes","") -> 0
A142: gemini-2.0-pro-exp-02-05 | B142: 0.5 | C142: 0.5 | D142: 30 | E142: =AVERAGEIFS('Raw Data'!$N:$N,'Raw Data'!$B:$B,"gemini-2.0-pro-exp-02-05",'Raw Data'!$C:$C,"0.5",'Raw Data'!$D:$D,"0.5",'Raw Data'!$E:$E,"30") -> 0 | F142: =AVERAGEIFS('Raw Data'!$J:$J,'Raw Data'!$B:$B,"gemini-2.0-pro-exp-02-05",'Raw Data'!$C:$C,"0.5",'Raw Data'!$D:$D,"0.5",'Raw Data'!$E:$E,"30") -> 0 | G142: =AVERAGEIFS('Raw Data'!$K:$K,'Raw Data'!$B:$B,"gemini-2.0-pro-exp-02-05",'Raw Data'!$C:$C,"0.5",'Raw Data'!$D:$D,"0.5",'Raw Data'!$E:$E,"30") -> 0 | H142: =AVERAGEIFS('Raw Data'!$O:$O,'Raw Data'!$B:$B,"gemini-2.0-pro-exp-02-05",'Raw Data'!$C:$C,"0.5",'Raw Data'!$D:$D,"0.5",'Raw Data'!$E:$E,"30") -> 0 | I142: =A142 & " (T:" & B142 & ", p:" & C142 & ", k:" & D142 & ")" -> 0 | J142: =RANK.EQ(E142,$E$2:$E$37,0) -> 0 | K142: =RANK.EQ(F142,$F$2:$F$37,1) -> 0 | L142: =RANK.EQ(G142,$G$2:$G$37,1) -> 0 | M142: =RANK.EQ(H142,$H$2:$H$37,1) -> 0 | N142: =AVERAGE(J142,K142,L142,M142) -> 0 | O142: =IF(N142=MIN($N$2:$N$37),"Yes","") -> 0 | P142: =IF(N142=MINIFS($N$2:$N$37,$A$2:$A$37,A142),"Yes","") -> 0
A147: gemini-2.0-pro-exp-02-05 | B147: 0.5 | C147: 0.95 | D147: 100 | E147: =AVERAGEIFS('Raw Data'!$N:$N,'Raw Data'!$B:$B,"gemini-2.0-pro-exp-02-05",'Raw Data'!$C:$C,"0.5",'Raw Data'!$D:$D,"0.95",'Raw Data'!$E:$E,"100") -> 0 | F147: =AVERAGEIFS('Raw Data'!$J:$J,'Raw Data'!$B:$B,"gemini-2.0-pro-exp-02-05",'Raw Data'!$C:$C,"0.5",'Raw Data'!$D:$D,"0.95",'Raw Data'!$E:$E,"100") -> 0 | G147: =AVERAGEIFS('Raw Data'!$K:$K,'Raw Data'!$B:$B,"gemini-2.0-pro-exp-02-05",'Raw Data'!$C:$C,"0.5",'Raw Data'!$D:$D,"0.95",'Raw Data'!$E:$E,"100") -> 0 | H147: =AVERAGEIFS('Raw Data'!$O:$O,'Raw Data'!$B:$B,"gemini-2.0-pro-exp-02-05",'Raw Data'!$C:$C,"0.5",'Raw Data'!$D:$D,"0.95",'Raw Data'!$E:$E,"100") -> 0 | I147: =A147 & " (T:" & B147 & ", p:" & C147 & ", k:" & D147 & ")" -> 0 | J147: =RANK.EQ(E147,$E$2:$E$37,0) -> 0 | K147: =RANK.EQ(F147,$F$2:$F$37,1) -> 0 | L147: =RANK.EQ(G147,$G$2:$G$37,1) -> 0 | M147: =RANK.EQ(H147,$H$2:$H$37,1) -> 0 | N147: =AVERAGE(J147,K147,L147,M147) -> 0 | O147: =IF(N147=MIN($N$2:$N$37),"Yes","") -> 0 | P147: =IF(N147=MINIFS($N$2:$N$37,$A$2:$A$37,A147),"Yes","") -> 0
A152: gemini-2.0-pro-exp-02-05 | B152: 1 | C152: 0.1 | D152: 10 | E152: =AVERAGEIFS('Raw Data'!$N:$N,'Raw Data'!$B:$B,"gemini-2.0-pro-exp-02-05",'Raw Data'!$C:$C,"1.0",'Raw Data'!$D:$D,"0.1",'Raw Data'!$E:$E,"10") -> 0 | F152: =AVERAGEIFS('Raw Data'!$J:$J,'Raw Data'!$B:$B,"gemini-2.0-pro-exp-02-05",'Raw Data'!$C:$C,"1.0",'Raw Data'!$D:$D,"0.1",'Raw Data'!$E:$E,"10") -> 0 | G152: =AVERAGEIFS('Raw Data'!$K:$K,'Raw Data'!$B:$B,"gemini-2.0-pro-exp-02-05",'Raw Data'!$C:$C,"1.0",'Raw Data'!$D:$D,"0.1",'Raw Data'!$E:$E,"10") -> 0 | H152: =AVERAGEIFS('Raw Data'!$O:$O,'Raw Data'!$B:$B,"gemini-2.0-pro-exp-02-05",'Raw Data'!$C:$C,"1.0",'Raw Data'!$D:$D,"0.1",'Raw Data'!$E:$E,"10") -> 0 | I152: =A152 & " (T:" & B152 & ", p:" & C152 & ", k:" & D152 & ")" -> 0 | J152: =RANK.EQ(E152,$E$2:$E$37,0) -> 0 | K152: =RANK.EQ(F152,$F$2:$F$37,1) -> 0 | L152: =RANK.EQ(G152,$G$2:$G$37,1) -> 0 | M152: =RANK.EQ(H152,$H$2:$H$37,1) -> 0 | N152: =AVERAGE(J152,K152,L152,M152) -> 0 | O152: =IF(N152=MIN($N$2:$N$37),"Yes","") -> 0 | P152: =IF(N152=MINIFS($N$2:$N$37,$A$2:$A$37,A152),"Yes","") -> 0
A157: gemini-2.0-pro-exp-02-05 | B157: 1 | C157: 0.5 | D157: 30 | E157: =AVERAGEIFS('Raw Data'!$N:$N,'Raw Data'!$B:$B,"gemini-2.0-pro-exp-02-05",'Raw Data'!$C:$C,"1.0",'Raw Data'!$D:$D,"0.5",'Raw Data'!$E:$E,"30") -> 0 | F157: =AVERAGEIFS('Raw Data'!$J:$J,'Raw Data'!$B:$B,"gemini-2.0-pro-exp-02-05",'Raw Data'!$C:$C,"1.0",'Raw Data'!$D:$D,"0.5",'Raw Data'!$E:$E,"30") -> 0 | G157: =AVERAGEIFS('Raw Data'!$K:$K,'Raw Data'!$B:$B,"gemini-2.0-pro-exp-02-05",'Raw Data'!$C:$C,"1.0",'Raw Data'!$D:$D,"0.5",'Raw Data'!$E:$E,"30") -> 0 | H157: =AVERAGEIFS('Raw Data'!$O:$O,'Raw Data'!$B:$B,"gemini-2.0-pro-exp-02-05",'Raw Data'!$C:$C,"1.0",'Raw Data'!$D:$D,"0.5",'Raw Data'!$E:$E,"30") -> 0 | I157: =A157 & " (T:" & B157 & ", p:" & C157 & ", k:" & D157 & ")" -> 0 | J157: =RANK.EQ(E157,$E$2:$E$37,0) -> 0 | K157: =RANK.EQ(F157,$F$2:$F$37,1) -> 0 | L157: =RANK.EQ(G157,$G$2:$G$37,1) -> 0 | M157: =RANK.EQ(H157,$H$2:$H$37,1) -> 0 | N157: =AVERAGE(J157,K157,L157,M157) -> 0 | O157: =IF(N157=MIN($N$2:$N$37),"Yes","") -> 0 | P157: =IF(N157=MINIFS($N$2:$N$37,$A$2:$A$37,A157),"Yes","") -> 0
A162: gemini-2.0-pro-exp-02-05 | B162: 1 | C162: 0.95 | D162: 100 | E162: =AVERAGEIFS('Raw Data'!$N:$N,'Raw Data'!$B:$B,"gemini-2.0-pro-exp-02-05",'Raw Data'!$C:$C,"1.0",'Raw Data'!$D:$D,"0.95",'Raw Data'!$E:$E,"100") -> 0 | F162: =AVERAGEIFS('Raw Data'!$J:$J,'Raw Data'!$B:$B,"gemini-2.0-pro-exp-02-05",'Raw Data'!$C:$C,"1.0",'Raw Data'!$D:$D,"0.95",'Raw Data'!$E:$E,"100") -> 0 | G162: =AVERAGEIFS('Raw Data'!$K:$K,'Raw Data'!$B:$B,"gemini-2.0-pro-exp-02-05",'Raw Data'!$C:$C,"1.0",'Raw Data'!$D:$D,"0.95",'Raw Data'!$E:$E,"100") -> 0 | H162: =AVERAGEIFS('Raw Data'!$O:$O,'Raw Data'!$B:$B,"gemini-2.0-pro-exp-02-05",'Raw Data'!$C:$C,"1.0",'Raw Data'!$D:$D,"0.95",'Raw Data'!$E:$E,"100") -> 0 | I162: =A162 & " (T:" & B162 & ", p:" & C162 & ", k:" & D162 & ")" -> 0 | J162: =RANK.EQ(E162,$E$2:$E$37,0) -> 0 | K162: =RANK.EQ(F162,$F$2:$F$37,1) -> 0 | L162: =RANK.EQ(G162,$G$2:$G$37,1) -> 0 | M162: =RANK.EQ(H162,$H$2:$H$37,1) -> 0 | N162: =AVERAGE(J162,K162,L162,M162) -> 0 | O162: =IF(N162=MIN($N$2:$N$37),"Yes","") -> 0 | P162: =IF(N162=MINIFS($N$2:$N$37,$A$2:$A$37,A162),"Yes","") -> 0
