Workbook

Sheet Raw Data
A1: ID | B1: model | C1: temperature | D1: top_p | E1: top_k | F1: code | G1: result | H1: true_count | I1: false_count | J1: execution_time | K1: memory_usage_MB | L1: algorithmic_complexity | M1: Total Tests | N1: Accuracy | O1: Numeric Complexity
A2: 1 | B2: gemini-2.0-flash-lite | C2: 0 | D2: 0.1 | E2: 10 | F2: class ListNode: def __init__(self, val=0, next=None): self.val = val self.next = next def addTwoNumbers(l1: ListNode, l2: ListNode) -> ListNode: """ Adds two numbers represented as linked lists. Args: l1: The first linked list. l2: The second linked list. Returns: The sum as a linked list. """ dummy_head = ListNode(0) current = dummy_head carry = 0 while l1 or l2 or carry: sum_val = carry if l1: sum_val += l1.val l1 = l1.next if l2: sum_val += l2.val l2 = l2.next carry = sum_val // 10 current.next = ListNode(sum_val % 10) current = current.next return dummy_head.next def list_to_linked_list(lst): """Converts a list to a linked list.""" dummy_head = ListNode(0) current = dummy_head for val in lst: current.next = ListNode(val) current = current.next return dummy_head.next def linked_list_to_list(head): """Converts a linked list to a list.""" result = [] current = head while current: result.append(current.val) current = current.next return result def test_add_two_numbers(): """Tests the addTwoNumbers function.""" tests = [ ([2, 4, 3], [5, 6, 4], [7, 0, 8]), ([0], [0], [0]), ([9, 9, 9, 9, 9, 9, 9], [9, 9, 9, 9], [8, 9, 9, 9, 0, 0, 0, 1]), ([1, 2, 3], [4, 5, 6], [5, 7, 9]), ([1], [9, 9], [0, 0, 1]) ] correct_tests = 0 for i, (l1_list, l2_list, expected_list) in enumerate(tests): l1 = list_to_linked_list(l1_list) l2 = list_to_linked_list(l2_list) result_linked_list = addTwoNumbers(l1, l2) result_list = linked_list_to_list(result_linked_list) if result_list == expected_list: print(True) correct_tests += 1 else: print(False) print(f"{correct_tests}/{len(tests)}") if __name__ == '__main__': test_add_two_numbers() | G2: True_x000D_ True_x000D_ True_x000D_ True_x000D_ True_x000D_ 5/5 | H2: 5 | I2: 0 | J2: 0.14 | K2: 2.02 | L2: loops: 4, conditionals: 4 | M2: =H2+I2 -> 0 | N2: =SI(M2>0,H2/M2,"") -> 0 | O2: =VALOR(ESPACIOS(EXTRAE(L2;HALLAR(":";L2)+1;HALLAR(",";L2)-HALLAR(":";L2)-1)))+VALOR(ESPACIOS(EXTRAE(L2;HALLAR("conditionals:";L2)+13;LARGO(L2))))) -> 0
A3: 2 | B3: gemini-2.0-flash-lite | C3: 0 | D3: 0.1 | E3: 10 | F3: def lengthOfLongestSubstring(s: str) -> int: """ Finds the length of the longest substring without repeating characters. Args: s: The input string. Returns: The length of the longest substring without repeating characters. """ if not s: return 0 max_length = 0 start = 0 char_index_map = {} # Store the index of each character for end, char in enumerate(s): if char in char_index_map and char_index_map[char] >= start: # Repeating character found within the current window start = char_index_map[char] + 1 char_index_map[char] = end max_length = max(max_length, end - start + 1) return max_length def test_length_of_longest_substring(): """Tests the lengthOfLongestSubstring function.""" tests = [ ("abcabcbb", 3), ("bbbbb", 1), ("pwwkew", 3), ("", 0), (" ", 1), ("au", 2), ("dvdf", 3), ("tmmzuxt", 5) ] correct_tests = 0 for s, expected_length in tests: result = lengthOfLongestSubstring(s) if result == expected_length: print(True) correct_tests += 1 else: print(False) print(f"{correct_tests}/{len(tests)}") if __name__ == '__main__': test_length_of_longest_substring() | G3: True_x000D_ True_x000D_ True_x000D_ True_x000D_ True_x000D_ True_x000D_ True_x000D_ True_x000D_ 8/8 | H3: 8 | I3: 0 | J3: 0.11 | K3: 2.01 | L3: loops: 2, conditionals: 4 | M3: =H3+I3 -> 0 | N3: =SI(M3>0,H3/M3,"") -> 0 | O3: =VALOR(ESPACIOS(EXTRAE(L3;HALLAR(":";L3)+1;HALLAR(",";L3)-HALLAR(":";L3)-1)))+VALOR(ESPACIOS(EXTRAE(L3;HALLAR("conditionals:";L3)+13;LARGO(L3))))) -> 0
A4: 3 | B4: gemini-2.0-flash-lite | C4: 0 | D4: 0.1 | E4: 10 | F4: def findMedianSortedArrays(nums1: list[int], nums2: list[int]) -> float: """ Finds the median of two sorted arrays. Args: nums1: The first sorted array. nums2: The second sorted array. Returns: The median of the two sorted arrays. """ merged_array = sorted(nums1 + nums2) merged_length = len(merged_array) if merged_length == 0: return 0.0 if merged_length % 2 == 0: # Even length, median is the average of the middle two elements mid1 = merged_array[merged_length // 2 - 1] mid2 = merged_array[merged_length // 2] return (mid1 + mid2) / 2.0 else: # Odd length, median is the middle element return float(merged_array[merged_length // 2]) def test_find_median_sorted_arrays(): """Tests the findMedianSortedArrays function.""" tests = [ ([1, 3], [2], 2.0), ([1, 2], [3, 4], 2.5), ([0, 0], [0, 0], 0.0), ([], [1], 1.0), ([2], [], 2.0), ([1, 2, 3], [4, 5, 6], 3.5), ([4, 5, 6], [1, 2, 3], 3.5), ([1, 3], [2, 7], 3.0), ([1, 2, 3], [2, 4, 6], 2.5) ] correct_tests = 0 for nums1, nums2, expected_median in tests: result = findMedianSortedArrays(nums1, nums2) if abs(result - expected_median) < 1e-5: # Use a small tolerance for floating-point comparisons print(True) correct_tests += 1 else: print(False) print(f"{correct_tests}/{len(tests)}") if __name__ == '__main__': test_find_median_sorted_arrays() | G4: True_x000D_ True_x000D_ True_x000D_ True_x000D_ True_x000D_ True_x000D_ True_x000D_ False_x000D_ True_x000D_ 8/9 | H4: 8 | I4: 1 | J4: 0.11 | K4: 2.01 | L4: loops: 1, conditionals: 4 | M4: =H4+I4 -> 0 | N4: =SI(M4>0,H4/M4,"") -> 0 | O4: =VALOR(ESPACIOS(EXTRAE(L4;HALLAR(":";L4)+1;HALLAR(",";L4)-HALLAR(":";L4)-1)))+VALOR(ESPACIOS(EXTRAE(L4;HALLAR("conditionals:";L4)+13;LARGO(L4))))) -> 0
A5: 4 | B5: gemini-2.0-flash-lite | C5: 0 | D5: 0.1 | E5: 10 | F5: def isMatch(s: str, p: str) -> bool: """ Implements regular expression matching with support for '.' and '*'. Args: s: The input string. p: The pattern. Returns: True if the pattern matches the entire input string, False otherwise. """ s_len = len(s) p_len = len(p) # dp[i][j] represents whether s[:i] matches p[:j] dp = [[False] * (p_len + 1) for _ in range(s_len + 1)] # Base case: empty string matches empty pattern dp[0][0] = True # Handle patterns like a*, a*b*, a*b*c* for j in range(1, p_len + 1): if p[j - 1] == '*': dp[0][j] = dp[0][j - 2] # '*' matches zero occurrences of the preceding character # Fill the dp table for i in range(1, s_len + 1): for j in range(1, p_len + 1): if p[j - 1] == '.' or p[j - 1] == s[i - 1]: # Current characters match dp[i][j] = dp[i - 1][j - 1] elif p[j - 1] == '*': # '*' case dp[i][j] = dp[i][j - 2] # '*' matches zero occurrences of the preceding character if p[j - 2] == '.' or p[j - 2] == s[i - 1]: dp[i][j] = dp[i][j] or dp[i - 1][j] # '*' matches one or more occurrences else: # Characters don't match dp[i][j] = False return dp[s_len][p_len] def test_isMatch(): """Tests the isMatch function.""" tests = [ ("aa", "a", False), ("aa", "a*", True), ("ab", ".*", True), ("aab", "c*a*b", True), ("mississippi", "mis*is*p*.", False), ("a", "ab*", True), ("abc", ".*", True), ("abc", "a.c", True), ("abc", "a.d", False), ("aaa", "a*a", True), ("aaa", "ab*a*c*a", True), ("a", ".*..", False), ("ab", ".*c", False), ("aaaaaaaaaaaaab", "a*a*a*a*a*a*a*a*a*a*c", False) ] correct_tests = 0 for s, p, expected in tests: result = isMatch(s, p) if result == expected: print(True) correct_tests += 1 else: print(False) print(f"{correct_tests}/{len(tests)}") if __name__ == '__main__': test_isMatch() | G5: True_x000D_ True_x000D_ True_x000D_ True_x000D_ True_x000D_ True_x000D_ True_x000D_ True_x000D_ True_x000D_ True_x000D_ True_x000D_ True_x000D_ True_x000D_ True_x000D_ 14/14 | H5: 14 | I5: 0 | J5: 0.11 | K5: 2.05 | L5: loops: 4, conditionals: 6 | M5: =H5+I5 -> 0 | N5: =SI(M5>0,H5/M5,"") -> 0 | O5: =VALOR(ESPACIOS(EXTRAE(L5;HALLAR(":";L5)+1;HALLAR(",";L5)-HALLAR(":";L5)-1)))+VALOR(ESPACIOS(EXTRAE(L5;HALLAR("conditionals:";L5)+13;LARGO(L5))))) -> 0
A6: 5 | B6: gemini-2.0-flash-lite | C6: 0 | D6: 0.1 | E6: 10 | F6: import heapq class ListNode: def __init__(self, val=0, next=None): self.val = val self.next = next def mergeKLists(lists: list[ListNode]) -> ListNode: """ Merges k sorted linked lists into one sorted linked list. Args: lists: A list of sorted linked lists. Returns: The merged sorted linked list. """ # Use a min-heap to efficiently merge the lists heap = [] for i, head in enumerate(lists): if head: heapq.heappush(heap, (head.val, i, head)) # (value, list_index, node) dummy_head = ListNode() current = dummy_head while heap: val, list_index, node = heapq.heappop(heap) current.next = node current = current.next if node.next: heapq.heappush(heap, (node.next.val, list_index, node.next)) return dummy_head.next def list_to_linked_list(lst): """Converts a list to a linked list.""" dummy_head = ListNode() current = dummy_head for val in lst: current.next = ListNode(val) current = current.next return dummy_head.next def linked_list_to_list(head): """Converts a linked list to a list.""" result = [] current = head while current: result.append(current.val) current = current.next return result def test_merge_k_lists(): """Tests the mergeKLists function.""" tests = [ ([[1, 4, 5], [1, 3, 4], [2, 6]], [1, 1, 2, 3, 4, 4, 5, 6]), ([], []), ([[]], []), ([[1, 2, 3], [], [4, 5, 6]], [1, 2, 3, 4, 5, 6]), ([[-1, 5, 11], [6, 10], [2, 3, 4, 7, 8, 9]], [-1, 2, 3, 4, 5, 6, 7, 8, 9, 10, 11]), ([[] , [1]], [1]) ] correct_tests = 0 for lists_input, expected_output in tests: lists = [list_to_linked_list(lst) for lst in lists_input] merged_list = mergeKLists(lists) result = linked_list_to_list(merged_list) if result == expected_output: print(True) correct_tests += 1 else: print(False) print(f"{correct_tests}/{len(tests)}") if __name__ == '__main__': test_merge_k_lists() | G6: True_x000D_ True_x000D_ True_x000D_ True_x000D_ True_x000D_ True_x000D_ 6/6 | H6: 6 | I6: 0 | J6: 0.11 | K6: 2 | L6: loops: 5, conditionals: 4 | M6: =H6+I6 -> 0 | N6: =SI(M6>0,H6/M6,"") -> 0 | O6: =VALOR(ESPACIOS(EXTRAE(L6;HALLAR(":";L6)+1;HALLAR(",";L6)-HALLAR(":";L6)-1)))+VALOR(ESPACIOS(EXTRAE(L6;HALLAR("conditionals:";L6)+13;LARGO(L6))))) -> 0
A7: 1 | B7: gemini-2.0-flash-lite | C7: 0 | D7: 0.5 | E7: 30 | F7: class ListNode: def __init__(self, val=0, next=None): self.val = val self.next = next def addTwoNumbers(l1: ListNode, l2: ListNode) -> ListNode: """ Adds two numbers represented as linked lists. Args: l1: The first linked list. l2: The second linked list. Returns: The sum as a linked list. """ dummy_head = ListNode(0) current = dummy_head carry = 0 while l1 or l2 or carry: sum_val = carry if l1: sum_val += l1.val l1 = l1.next if l2: sum_val += l2.val l2 = l2.next carry = sum_val // 10 current.next = ListNode(sum_val % 10) current = current.next return dummy_head.next def list_to_linked_list(lst): """Converts a list to a linked list.""" dummy_head = ListNode(0) current = dummy_head for val in lst: current.next = ListNode(val) current = current.next return dummy_head.next def linked_list_to_list(head): """Converts a linked list to a list.""" result = [] current = head while current: result.append(current.val) current = current.next return result def test_add_two_numbers(): """Tests the addTwoNumbers function.""" tests = [ ([2, 4, 3], [5, 6, 4], [7, 0, 8]), ([0], [0], [0]), ([9, 9, 9, 9, 9, 9, 9], [9, 9, 9, 9], [8, 9, 9, 9, 0, 0, 0, 1]), ([1, 2, 3], [4, 5, 6], [5, 7, 9]), ([1], [9, 9], [0, 0, 1]) ] correct_tests = 0 for i, (l1_list, l2_list, expected_list) in enumerate(tests): l1 = list_to_linked_list(l1_list) l2 = list_to_linked_list(l2_list) result_linked_list = addTwoNumbers(l1, l2) result_list = linked_list_to_list(result_linked_list) if result_list == expected_list: print(True) correct_tests += 1 else: print(False) print(f"{correct_tests}/{len(tests)}") if __name__ == '__main__': test_add_two_numbers() | G7: True_x000D_ True_x000D_ True_x000D_ True_x000D_ True_x000D_ 5/5 | H7: 5 | I7: 0 | J7: 0.11 | K7: 2.01 | L7: loops: 4, conditionals: 4 | M7: =H7+I7 -> 0 | N7: =SI(M7>0,H7/M7,"") -> 0 | O7: =VALOR(ESPACIOS(EXTRAE(L7;HALLAR(":";L7)+1;HALLAR(",";L7)-HALLAR(":";L7)-1)))+VALOR(ESPACIOS(EXTRAE(L7;HALLAR("conditionals:";L7)+13;LARGO(L7))))) -> 0
A8: 2 | B8: gemini-2.0-flash-lite | C8: 0 | D8: 0.5 | E8: 30 | F8: def lengthOfLongestSubstring(s: str) -> int: """ Finds the length of the longest substring without repeating characters. Args: s: The input string. Returns: The length of the longest substring without repeating characters. """ if not s: return 0 max_length = 0 start = 0 char_index_map = {} # Store the index of each character for end, char in enumerate(s): if char in char_index_map and char_index_map[char] >= start: # Repeating character found within the current window start = char_index_map[char] + 1 char_index_map[char] = end max_length = max(max_length, end - start + 1) return max_length def test_length_of_longest_substring(): """Tests the lengthOfLongestSubstring function.""" tests = [ ("abcabcbb", 3), ("bbbbb", 1), ("pwwkew", 3), ("", 0), (" ", 1), ("au", 2), ("dvdf", 3), ("tmmzuxt", 5) ] correct_tests = 0 for s, expected_length in tests: result = lengthOfLongestSubstring(s) if result == expected_length: print(True) correct_tests += 1 else: print(False) print(f"{correct_tests}/{len(tests)}") if __name__ == '__main__': test_length_of_longest_substring() | G8: True_x000D_ True_x000D_ True_x000D_ True_x000D_ True_x000D_ True_x000D_ True_x000D_ True_x000D_ 8/8 | H8: 8 | I8: 0 | J8: 0.11 | K8: 2.01 | L8: loops: 2, conditionals: 4 | M8: =H8+I8 -> 0 | N8: =SI(M8>0,H8/M8,"") -> 0 | O8: =VALOR(ESPACIOS(EXTRAE(L8;HALLAR(":";L8)+1;HALLAR(",";L8)-HALLAR(":";L8)-1)))+VALOR(ESPACIOS(EXTRAE(L8;HALLAR("conditionals:";L8)+13;LARGO(L8))))) -> 0
A9: 3 | B9: gemini-2.0-flash-lite | C9: 0 | D9: 0.5 | E9: 30 | F9: def findMedianSortedArrays(nums1: list[int], nums2: list[int]) -> float: """ Finds the median of two sorted arrays. Args: nums1: The first sorted array. nums2: The second sorted array. Returns: The median of the two sorted arrays. """ merged_array = sorted(nums1 + nums2) merged_length = len(merged_array) if merged_length == 0: return 0.0 if merged_length % 2 == 0: # Even length, median is the average of the middle two elements mid1 = merged_array[merged_length // 2 - 1] mid2 = merged_array[merged_length // 2] return (mid1 + mid2) / 2.0 else: # Odd length, median is the middle element return float(merged_array[merged_length // 2]) def test_find_median_sorted_arrays(): """Tests the findMedianSortedArrays function.""" tests = [ ([1, 3], [2], 2.0), ([1, 2], [3, 4], 2.5), ([0, 0], [0, 0], 0.0), ([], [1], 1.0), ([2], [], 2.0), ([1, 2, 3], [4, 5, 6], 3.5), ([4, 5, 6], [1, 2, 3], 3.5), ([1, 3], [2, 7], 3.0), ([1, 2, 3], [2, 4, 6], 2.5) ] correct_tests = 0 for nums1, nums2, expected_median in tests: result = findMedianSortedArrays(nums1, nums2) if abs(result - expected_median) < 1e-5: # Use a small tolerance for floating-point comparisons print(True) correct_tests += 1 else: print(False) print(f"{correct_tests}/{len(tests)}") if __name__ == '__main__': test_find_median_sorted_arrays() | G9: True_x000D_ True_x000D_ True_x000D_ True_x000D_ True_x000D_ True_x000D_ True_x000D_ False_x000D_ True_x000D_ 8/9 | H9: 8 | I9: 1 | J9: 0.11 | K9: 2.01 | L9: loops: 1, conditionals: 4 | M9: =H9+I9 -> 0 | N9: =SI(M9>0,H9/M9,"") -> 0 | O9: =VALOR(ESPACIOS(EXTRAE(L9;HALLAR(":";L9)+1;HALLAR(",";L9)-HALLAR(":";L9)-1)))+VALOR(ESPACIOS(EXTRAE(L9;HALLAR("conditionals:";L9)+13;LARGO(L9))))) -> 0
A10: 4 | B10: gemini-2.0-flash-lite | C10: 0 | D10: 0.5 | E10: 30 | F10: def isMatch(s: str, p: str) -> bool: """ Implements regular expression matching with support for '.' and '*'. Args: s: The input string. p: The pattern. Returns: True if the pattern matches the entire input string, False otherwise. """ s_len = len(s) p_len = len(p) # dp[i][j] represents whether s[:i] matches p[:j] dp = [[False] * (p_len + 1) for _ in range(s_len + 1)] # Base case: empty string matches empty pattern dp[0][0] = True # Handle patterns like a*, a*b*, a*b*c* for j in range(1, p_len + 1): if p[j - 1] == '*': dp[0][j] = dp[0][j - 2] # '*' matches zero occurrences of the preceding character # Fill the dp table for i in range(1, s_len + 1): for j in range(1, p_len + 1): if p[j - 1] == '.' or p[j - 1] == s[i - 1]: # Current characters match dp[i][j] = dp[i - 1][j - 1] elif p[j - 1] == '*': # '*' case dp[i][j] = dp[i][j - 2] # '*' matches zero occurrences of the preceding character if p[j - 2] == '.' or p[j - 2] == s[i - 1]: dp[i][j] = dp[i][j] or dp[i - 1][j] # '*' matches one or more occurrences else: # Characters don't match dp[i][j] = False return dp[s_len][p_len] def test_isMatch(): """Tests the isMatch function.""" tests = [ ("aa", "a", False), ("aa", "a*", True), ("ab", ".*", True), ("aab", "c*a*b", True), ("mississippi", "mis*is*p*.", False), ("a", "ab*", True), ("abc", ".*", True), ("abc", "a.c", True), ("abc", "a.d", False), ("aaa", "a*a", True), ("aaa", "ab*a*c*a", True), ("a", ".*..", False), ("ab", ".*c", False), ("aaaaaaaaaaaaab", "a*a*a*a*a*a*a*a*a*a*c", False) ] correct_tests = 0 for s, p, expected in tests: result = isMatch(s, p) if result == expected: print(True) correct_tests += 1 else: print(False) print(f"{correct_tests}/{len(tests)}") if __name__ == '__main__': test_isMatch() | G10: True_x000D_ True_x000D_ True_x000D_ True_x000D_ True_x000D_ True_x000D_ True_x000D_ True_x000D_ True_x000D_ True_x000D_ True_x000D_ True_x000D_ True_x000D_ True_x000D_ 14/14 | H10: 14 | I10: 0 | J10: 0.11 | K10: 2.04 | L10: loops: 4, conditionals: 6 | M10: =H10+I10 -> 0 | N10: =SI(M10>0,H10/M10,"") -> 0 | O10: =VALOR(ESPACIOS(EXTRAE(L10;HALLAR(":";L10)+1;HALLAR(",";L10)-HALLAR(":";L10)-1)))+VALOR(ESPACIOS(EXTRAE(L10;HALLAR("conditionals:";L10)+13;LARGO(L10))))) -> 0
A11: 5 | B11: gemini-2.0-flash-lite | C11: 0 | D11: 0.5 | E11: 30 | F11: import heapq class ListNode: def __init__(self, val=0, next=None): self.val = val self.next = next def mergeKLists(lists: list[ListNode]) -> ListNode: """ Merges k sorted linked lists into one sorted linked list. Args: lists: A list of sorted linked lists. Returns: The merged sorted linked list. """ # Use a min-heap to efficiently merge the lists heap = [] for i, head in enumerate(lists): if head: heapq.heappush(heap, (head.val, i, head)) # (value, list_index, node) dummy_head = ListNode() current = dummy_head while heap: val, list_index, node = heapq.heappop(heap) current.next = node current = current.next if node.next: heapq.heappush(heap, (node.next.val, list_index, node.next)) return dummy_head.next def list_to_linked_list(lst): """Converts a list to a linked list.""" dummy_head = ListNode() current = dummy_head for val in lst: current.next = ListNode(val) current = current.next return dummy_head.next def linked_list_to_list(head): """Converts a linked list to a list.""" result = [] current = head while current: result.append(current.val) current = current.next return result def test_merge_k_lists(): """Tests the mergeKLists function.""" tests = [ ([[1, 4, 5], [1, 3, 4], [2, 6]], [1, 1, 2, 3, 4, 4, 5, 6]), ([], []), ([[]], []), ([[1, 2, 3], [], [4, 5, 6]], [1, 2, 3, 4, 5, 6]), ([[-1, 5, 11], [6, 10], [2, 3, 4, 7, 8, 9]], [-1, 2, 3, 4, 5, 6, 7, 8, 9, 10, 11]), ([[] , [1]], [1]) ] correct_tests = 0 for lists_input, expected_output in tests: lists = [list_to_linked_list(lst) for lst in lists_input] merged_list = mergeKLists(lists) result = linked_list_to_list(merged_list) if result == expected_output: print(True) correct_tests += 1 else: print(False) print(f"{correct_tests}/{len(tests)}") if __name__ == '__main__': test_merge_k_lists() | G11: True_x000D_ True_x000D_ True_x000D_ True_x000D_ True_x000D_ True_x000D_ 6/6 | H11: 6 | I11: 0 | J11: 0.11 | K11: 2.05 | L11: loops: 5, conditionals: 4 | M11: =H11+I11 -> 0 | N11: =SI(M11>0,H11/M11,"") -> 0 | O11: =VALOR(ESPACIOS(EXTRAE(L11;HALLAR(":";L11)+1;HALLAR(",";L11)-HALLAR(":";L11)-1)))+VALOR(ESPACIOS(EXTRAE(L11;HALLAR("conditionals:";L11)+13;LARGO(L11))))) -> 0
A12: 1 | B12: gemini-2.0-flash-lite | C12: 0 | D12: 0.95 | E12: 100 | F12: class ListNode: def __init__(self, val=0, next=None): self.val = val self.next = next def addTwoNumbers(l1: ListNode, l2: ListNode) -> ListNode: """ Adds two numbers represented as linked lists. Args: l1: The first linked list. l2: The second linked list. Returns: The sum as a linked list. """ dummy_head = ListNode(0) current = dummy_head carry = 0 while l1 or l2 or carry: sum_val = carry if l1: sum_val += l1.val l1 = l1.next if l2: sum_val += l2.val l2 = l2.next carry = sum_val // 10 current.next = ListNode(sum_val % 10) current = current.next return dummy_head.next def list_to_linked_list(lst): """Converts a list to a linked list.""" dummy_head = ListNode(0) current = dummy_head for val in lst: current.next = ListNode(val) current = current.next return dummy_head.next def linked_list_to_list(head): """Converts a linked list to a list.""" result = [] current = head while current: result.append(current.val) current = current.next return result def test_add_two_numbers(): """Tests the addTwoNumbers function.""" tests = [ ([2, 4, 3], [5, 6, 4], [7, 0, 8]), ([0], [0], [0]), ([9, 9, 9, 9, 9, 9, 9], [9, 9, 9, 9], [8, 9, 9, 9, 0, 0, 0, 1]), ([1, 2, 3], [4, 5, 6], [5, 7, 9]), ([1], [9, 9], [0, 0, 1]) ] correct_tests = 0 for i, (l1_list, l2_list, expected_list) in enumerate(tests): l1 = list_to_linked_list(l1_list) l2 = list_to_linked_list(l2_list) result_linked_list = addTwoNumbers(l1, l2) result_list = linked_list_to_list(result_linked_list) if result_list == expected_list: print(True) correct_tests += 1 else: print(False) print(f"{correct_tests}/{len(tests)}") if __name__ == '__main__': test_add_two_numbers() | G12: True_x000D_ True_x000D_ True_x000D_ True_x000D_ True_x000D_ 5/5 | H12: 5 | I12: 0 | J12: 0.11 | K12: 2.01 | L12: loops: 4, conditionals: 4 | M12: =H12+I12 -> 0 | N12: =SI(M12>0,H12/M12,"") -> 0 | O12: =VALOR(ESPACIOS(EXTRAE(L12;HALLAR(":";L12)+1;HALLAR(",";L12)-HALLAR(":";L12)-1)))+VALOR(ESPACIOS(EXTRAE(L12;HALLAR("conditionals:";L12)+13;LARGO(L12))))) -> 0
A13: 2 | B13: gemini-2.0-flash-lite | C13: 0 | D13: 0.95 | E13: 100 | F13: def lengthOfLongestSubstring(s: str) -> int: """ Finds the length of the longest substring without repeating characters. Args: s: The input string. Returns: The length of the longest substring without repeating characters. """ if not s: return 0 max_length = 0 start = 0 char_index_map = {} # Store the index of each character for end, char in enumerate(s): if char in char_index_map and char_index_map[char] >= start: # Repeating character found within the current window start = char_index_map[char] + 1 char_index_map[char] = end max_length = max(max_length, end - start + 1) return max_length def test_length_of_longest_substring(): """Tests the lengthOfLongestSubstring function.""" tests = [ ("abcabcbb", 3), ("bbbbb", 1), ("pwwkew", 3), ("", 0), (" ", 1), ("au", 2), ("dvdf", 3), ("abba", 2) ] correct_tests = 0 for s, expected_length in tests: result = lengthOfLongestSubstring(s) if result == expected_length: print(True) correct_tests += 1 else: print(False) print(f"{correct_tests}/{len(tests)}") if __name__ == '__main__': test_length_of_longest_substring() | G13: True_x000D_ True_x000D_ True_x000D_ True_x000D_ True_x000D_ True_x000D_ True_x000D_ True_x000D_ 8/8 | H13: 8 | I13: 0 | J13: 0.11 | K13: 2.01 | L13: loops: 2, conditionals: 4 | M13: =H13+I13 -> 0 | N13: =SI(M13>0,H13/M13,"") -> 0 | O13: =VALOR(ESPACIOS(EXTRAE(L13;HALLAR(":";L13)+1;HALLAR(",";L13)-HALLAR(":";L13)-1)))+VALOR(ESPACIOS(EXTRAE(L13;HALLAR("conditionals:";L13)+13;LARGO(L13))))) -> 0
... A181: 5 | B181: gemini-2.0-pro-exp-02-05 | C181: 2 | D181: 0.95 | E181: 100 | F181: class ListNode: def __init__(self, val=0, next=None): self.val = val self.next = next def mergeKLists(lists): import heapq dummy = ListNode(-1) tail = dummy heap = [] for i, lst in enumerate(lists): if lst: heapq.heappush(heap, (lst.val, i, lst)) while heap: val, i, node = heapq.heappop(heap) tail.next = node tail = tail.next if node.next: heapq.heappush(heap, (node.next.val, i, node.next)) return dummy.next def list_to_linked_list(lst): dummy_head = ListNode(0) current = dummy_head for val in lst: current.next = ListNode(val) current = current.next return dummy_head.next def linked_list_to_list(head): lst = [] current = head while current: lst.append(current.val) current = current.next return lst def run_tests(): test_cases = [ ([[1, 4, 5], [1, 3, 4], [2, 6]], [1, 1, 2, 3, 4, 4, 5, 6]), ([], []), ([[]], []), ] test_results = [] correct_tests = 0 for lists, expected in test_cases: linked_lists = [list_to_linked_list(l) for l in lists] merged_list = mergeKLists(linked_lists) result_list = linked_list_to_list(merged_list) test_result = result_list == expected test_results.append(test_result) if(test_result): correct_tests+=1 print(test_result) print(f"{correct_tests}/{len(test_cases)}") run_tests() | G181: True_x000D_ True_x000D_ True_x000D_ 3/3 | H181: 3 | I181: 0 | J181: 0.11 | K181: 2.03 | L181: loops: 5, conditionals: 3 | M181: =H181+I181 -> 0 | N181: =SI(M181>0,H181/M181,"") -> 0 | O181: =VALOR(ESPACIOS(EXTRAE(L181;HALLAR(":";L181)+1;HALLAR(",";L181)-HALLAR(":";L181)-1)))+VALOR(ESPACIOS(EXTRAE(L181;HALLAR("conditionals:";L181)+13;LARGO(L181))))) -> 0

Sheet Comparisons
A1: Model | B1: Temperature | C1: top_p | D1: top_k | E1: Avg Accuracy | F1: Avg Time (s) | G1: Avg Memory (MB) | H1: Avg Complexity | I1: Config Label | J1: Rank Accuracy | K1: Rank Time | L1: Rank Memory | M1: Rank Complexity | N1: Composite Rank | O1: Global Best? | P1: Best per Model?
A2: gemini-2.0-flash | B2: 0.5 | C2: 0.95 | D2: 100 | E2: =PROMEDIO.SI.CONJUNTO('Raw Data'!$N:$N,'Raw Data'!$B:$B,"gemini-2.0-flash",'Raw Data'!$C:$C,"0.5",'Raw Data'!$D:$D,"0.95",'Raw Data'!$E:$E,"100") -> 0 | F2: =PROMEDIO.SI.CONJUNTO('Raw Data'!$J:$J,'Raw Data'!$B:$B,"gemini-2.0-flash",'Raw Data'!$C:$C,"0.5",'Raw Data'!$D:$D,"0.95",'Raw Data'!$E:$E,"100") -> 0 | G2: =PROMEDIO.SI.CONJUNTO('Raw Data'!$K:$K,'Raw Data'!$B:$B,"gemini-2.0-flash",'Raw Data'!$C:$C,"0.5",'Raw Data'!$D:$D,"0.95",'Raw Data'!$E:$E,"100") -> 0 | H2: =PROMEDIO.SI.CONJUNTO('Raw Data'!$O:$O,'Raw Data'!$B:$B,"gemini-2.0-flash",'Raw Data'!$C:$C,"0.5",'Raw Data'!$D:$D,"0.95",'Raw Data'!$E:$E,"100") -> 0 | I2: =A2 & " (T:" & B2 & ", p:" & C2 & ", k:" & D2 & ")" -> 0 | J2: =JERARQUIA.EQV(E2,$E$2:$E$37,0) -> 0 | K2: =JERARQUIA.EQV(F2,$F$2:$F$37,1) -> 0 | L2: =JERARQUIA.EQV(G2,$G$2:$G$37,1) -> 0 | M2: =JERARQUIA.EQV(H2,$H$2:$H$37,1) -> 0 | N2: =PROMEDIO(J2,K2,L2,M2) -> 0 | O2: =SI(N2=MIN($N$2:$N$37),"Yes","") -> 0 | P2: =SI(N2=MIN.SI.CONJUNTO($N$2:$N$37,$A$2:$A$37,A2),"Yes","") -> 0
A3: gemini-2.0-flash | B3: 2 | C3: 0.95 | D3: 100 | E3: =PROMEDIO.SI.CONJUNTO('Raw Data'!$N:$N,'Raw Data'!$B:$B,"gemini-2.0-flash",'Raw Data'!$C:$C,"2.0",'Raw Data'!$D:$D,"0.95",'Raw Data'!$E:$E,"100") -> 0 | F3: =PROMEDIO.SI.CONJUNTO('Raw Data'!$J:$J,'Raw Data'!$B:$B,"gemini-2.0-flash",'Raw Data'!$C:$C,"2.0",'Raw Data'!$D:$D,"0.95",'Raw Data'!$E:$E,"100") -> 0 | G3: =PROMEDIO.SI.CONJUNTO('Raw Data'!$K:$K,'Raw Data'!$B:$B,"gemini-2.0-flash",'Raw Data'!$C:$C,"2.0",'Raw Data'!$D:$D,"0.95",'Raw Data'!$E:$E,"100") -> 0 | H3: =PROMEDIO.SI.CONJUNTO('Raw Data'!$O:$O,'Raw Data'!$B:$B,"gemini-2.0-flash",'Raw Data'!$C:$C,"2.0",'Raw Data'!$D:$D,"0.95",'Raw Data'!$E:$E,"100") -> 0 | I3: =A3 & " (T:" & B3 & ", p:" & C3 & ", k:" & D3 & ")" -> 0 | J3: =JERARQUIA.EQV(E3,$E$2:$E$37,0) -> 0 | K3: =JERARQUIA.EQV(F3,$F$2:$F$37,1) -> 0 | L3: =JERARQUIA.EQV(G3,$G$2:$G$37,1) -> 0 | M3: =JERARQUIA.EQV(H3,$H$2:$H$37,1) -> 0 | N3: =PROMEDIO(J3,K3,L3,M3) -> 0 | O3: =SI(N3=MIN($N$2:$N$37),"Yes","") -> 0 | P3: =SI(N3=MIN.SI.CONJUNTO($N$2:$N$37,$A$2:$A$37,A3),"Yes","") -> 0
A4: gemini-2.0-flash | B4: 2 | C4: 0.5 | D4: 30 | E4: =PROMEDIO.SI.CONJUNTO('Raw Data'!$N:$N,'Raw Data'!$B:$B,"gemini-2.0-flash",'Raw Data'!$C:$C,"2.0",'Raw Data'!$D:$D,"0.5",'Raw Data'!$E:$E,"30") -> 0 | F4: =PROMEDIO.SI.CONJUNTO('Raw Data'!$J:$J,'Raw Data'!$B:$B,"gemini-2.0-flash",'Raw Data'!$C:$C,"2.0",'Raw Data'!$D:$D,"0.5",'Raw Data'!$E:$E,"30") -> 0 | G4: =PROMEDIO.SI.CONJUNTO('Raw Data'!$K:$K,'Raw Data'!$B:$B,"gemini-2.0-flash",'Raw Data'!$C:$C,"2.0",'Raw Data'!$D:$D,"0.5",'Raw Data'!$E:$E,"30") -> 0 | H4: =PROMEDIO.SI.CONJUNTO('Raw Data'!$O:$O,'Raw Data'!$B:$B,"gemini-2.0-flash",'Raw Data'!$C:$C,"2.0",'Raw Data'!$D:$D,"0.5",'Raw Data'!$E:$E,"30") -> 0 | I4: =A4 & " (T:" & B4 & ", p:" & C4 & ", k:" & D4 & ")" -> 0 | J4: =JERARQUIA.EQV(E4,$E$2:$E$37,0) -> 0 | K4: =JERARQUIA.EQV(F4,$F$2:$F$37,1) -> 0 | L4: =JERARQUIA.EQV(G4,$G$2:$G$37,1) -> 0 | M4: =JERARQUIA.EQV(H4,$H$2:$H$37,1) -> 0 | N4: =PROMEDIO(J4,K4,L4,M4) -> 0 | O4: =SI(N4=MIN($N$2:$N$37),"Yes","") -> 0 | P4: =SI(N4=MIN.SI.CONJUNTO($N$2:$N$37,$A$2:$A$37,A4),"Yes","") -> 0
A5: gemini-2.0-flash | B5: 2 | C5: 0.1 | D5: 10 | E5: =PROMEDIO.SI.CONJUNTO('Raw Data'!$N:$N,'Raw Data'!$B:$B,"gemini-2.0-flash",'Raw Data'!$C:$C,"2.0",'Raw Data'!$D:$D,"0.1",'Raw Data'!$E:$E,"10") -> 0 | F5: =PROMEDIO.SI.CONJUNTO('Raw Data'!$J:$J,'Raw Data'!$B:$B,"gemini-2.0-flash",'Raw Data'!$C:$C,"2.0",'Raw Data'!$D:$D,"0.1",'Raw Data'!$E:$E,"10") -> 0 | G5: =PROMEDIO.SI.CONJUNTO('Raw Data'!$K:$K,'Raw Data'!$B:$B,"gemini-2.0-flash",'Raw Data'!$C:$C,"2.0",'Raw Data'!$D:$D,"0.1",'Raw Data'!$E:$E,"10") -> 0 | H5: =PROMEDIO.SI.CONJUNTO('Raw Data'!$O:$O,'Raw Data'!$B:$B,"gemini-2.0-flash",'Raw Data'!$C:$C,"2.0",'Raw Data'!$D:$D,"0.1",'Raw Data'!$E:$E,"10") -> 0 | I5: =A5 & " (T:" & B5 & ", p:" & C5 & ", k:" & D5 & ")" -> 0 | J5: =JERARQUIA.EQV(E5,$E$2:$E$37,0) -> 0 | K5: =JERARQUIA.EQV(F5,$F$2:$F$37,1) -> 0 | L5: =JERARQUIA.EQV(G5,$G$2:$G$37,1) -> 0 | M5: =JERARQUIA.EQV(H5,$H$2:$H$37,1) -> 0 | N5: =PROMEDIO(J5,K5,L5,M5) -> 0 | O5: =SI(N5=MIN($N$2:$N$37),"Yes","") -> 0 | P5: =SI(N5=MIN.SI.CONJUNTO($N$2:$N$37,$A$2:$A$37,A5),"Yes","") -> 0
A6: gemini-2.0-flash | B6: 1 | C6: 0.95 | D6: 100 | E6: =PROMEDIO.SI.CONJUNTO('Raw Data'!$N:$N,'Raw Data'!$B:$B,"gemini-2.0-flash",'Raw Data'!$C:$C,"1.0",'Raw Data'!$D:$D,"0.95",'Raw Data'!$E:$E,"100") -> 0 | F6: =PROMEDIO.SI.CONJUNTO('Raw Data'!$J:$J,'Raw Data'!$B:$B,"gemini-2.0-flash",'Raw Data'!$C:$C,"1.0",'Raw Data'!$D:$D,"0.95",'Raw Data'!$E:$E,"100") -> 0 | G6: =PROMEDIO.SI.CONJUNTO('Raw Data'!$K:$K,'Raw Data'!$B:$B,"gemini-2.0-flash",'Raw Data'!$C:$C,"1.0",'Raw Data'!$D:$D,"0.95",'Raw Data'!$E:$E,"100") -> 0 | H6: =PROMEDIO.SI.CONJUNTO('Raw Data'!$O:$O,'Raw Data'!$B:$B,"gemini-2.0-flash",'Raw Data'!$C:$C,"1.0",'Raw Data'!$D:$D,"0.95",'Raw Data'!$E:$E,"100") -> 0 | I6: =A6 & " (T:" & B6 & ", p:" & C6 & ", k:" & D6 & ")" -> 0 | J6: =JERARQUIA.EQV(E6,$E$2:$E$37,0) -> 0 | K6: =JERARQUIA.EQV(F6,$F$2:$F$37,1) -> 0 | L6: =JERARQUIA.EQV(G6,$G$2:$G$37,1) -> 0 | M6: =JERARQUIA.EQV(H6,$H$2:$H$37,1) -> 0 | N6: =PROMEDIO(J6,K6,L6,M6) -> 0 | O6: =SI(N6=MIN($N$2:$N$37),"Yes","") -> 0 | P6: =SI(N6=MIN.SI.CONJUNTO($N$2:$N$37,$A$2:$A$37,A6),"Yes","") -> 0
A7: gemini-2.0-flash | B7: 1 | C7: 0.5 | D7: 30 | E7: =PROMEDIO.SI.CONJUNTO('Raw Data'!$N:$N,'Raw Data'!$B:$B,"gemini-2.0-flash",'Raw Data'!$C:$C,"1.0",'Raw Data'!$D:$D,"0.5",'Raw Data'!$E:$E,"30") -> 0 | F7: =PROMEDIO.SI.CONJUNTO('Raw Data'!$J:$J,'Raw Data'!$B:$B,"gemini-2.0-flash",'Raw Data'!$C:$C,"1.0",'Raw Data'!$D:$D,"0.5",'Raw Data'!$E:$E,"30") -> 0 | G7: =PROMEDIO.SI.CONJUNTO('Raw Data'!$K:$K,'Raw Data'!$B:$B,"gemini-2.0-flash",'Raw Data'!$C:$C,"1.0",'Raw Data'!$D:$D,"0.5",'Raw Data'!$E:$E,"30") -> 0 | H7: =PROMEDIO.SI.CONJUNTO('Raw Data'!$O:$O,'Raw Data'!$B:$B,"gemini-2.0-flash",'Raw Data'!$C:$C,"1.0",'Raw Data'!$D:$D,"0.5",'Raw Data'!$E:$E,"30") -> 0 | I7: =A7 & " (T:" & B7 & ", p:" & C7 & ", k:" & D7 & ")" -> 0 | J7: =JERARQUIA.EQV(E7,$E$2:$E$37,0) -> 0 | K7: =JERARQUIA.EQV(F7,$F$2:$F$37,1) -> 0 | L7: =JERARQUIA.EQV(G7,$G$2:$G$37,1) -> 0 | M7: =JERARQUIA.EQV(H7,$H$2:$H$37,1) -> 0 | N7: =PROMEDIO(J7,K7,L7,M7) -> 0 | O7: =SI(N7=MIN($N$2:$N$37),"Yes","") -> 0 | P7: =SI(N7=MIN.SI.CONJUNTO($N$2:$N$37,$A$2:$A$37,A7),"Yes","") -> 0
A8: gemini-2.0-flash | B8: 1 | C8: 0.1 | D8: 10 | E8: =PROMEDIO.SI.CONJUNTO('Raw Data'!$N:$N,'Raw Data'!$B:$B,"gemini-2.0-flash",'Raw Data'!$C:$C,"1.0",'Raw Data'!$D:$D,"0.1",'Raw Data'!$E:$E,"10") -> 0 | F8: =PROMEDIO.SI.CONJUNTO('Raw Data'!$J:$J,'Raw Data'!$B:$B,"gemini-2.0-flash",'Raw Data'!$C:$C,"1.0",'Raw Data'!$D:$D,"0.1",'Raw Data'!$E:$E,"10") -> 0 | G8: =PROMEDIO.SI.CONJUNTO('Raw Data'!$K:$K,'Raw Data'!$B:$B,"gemini-2.0-flash",'Raw Data'!$C:$C,"1.0",'Raw Data'!$D:$D,"0.1",'Raw Data'!$E:$E,"10") -> 0 | H8: =PROMEDIO.SI.CONJUNTO('Raw Data'!$O:$O,'Raw Data'!$B:$B,"gemini-2.0-flash",'Raw Data'!$C:$C,"1.0",'Raw Data'!$D:$D,"0.1",'Raw Data'!$E:$E,"10") -> 0 | I8: =A8 & " (T:" & B8 & ", p:" & C8 & ", k:" & D8 & ")" -> 0 | J8: =JERARQUIA.EQV(E8,$E$2:$E$37,0) -> 0 | K8: =JERARQUIA.EQV(F8,$F$2:$F$37,1) -> 0 | L8: =JERARQUIA.EQV(G8,$G$2:$G$37,1) -> 0 | M8: =JERARQUIA.EQV(H8,$H$2:$H$37,1) -> 0 | N8: =PROMEDIO(J8,K8,L8,M8) -> 0 | O8: =SI(N8=MIN($N$2:$N$37),"Yes","") -> 0 | P8: =SI(N8=MIN.SI.CONJUNTO($N$2:$N$37,$A$2:$A$37,A8),"Yes","") -> 0
A9: gemini-2.0-flash | B9: 0.5 | C9: 0.5 | D9: 30 | E9: =PROMEDIO.SI.CONJUNTO('Raw Data'!$N:$N,'Raw Data'!$B:$B,"gemini-2.0-flash",'Raw Data'!$C:$C,"0.5",'Raw Data'!$D:$D,"0.5",'Raw Data'!$E:$E,"30") -> 0 | F9: =PROMEDIO.SI.CONJUNTO('Raw Data'!$J:$J,'Raw Data'!$B:$B,"gemini-2.0-flash",'Raw Data'!$C:$C,"0.5",'Raw Data'!$D:$D,"0.5",'Raw Data'!$E:$E,"30") -> 0 | G9: =PROMEDIO.SI.CONJUNTO('Raw Data'!$K:$K,'Raw Data'!$B:$B,"gemini-2.0-flash",'Raw Data'!$C:$C,"0.5",'Raw Data'!$D:$D,"0.5",'Raw Data'!$E:$E,"30") -> 0 | H9: =PROMEDIO.SI.CONJUNTO('Raw Data'!$O:$O,'Raw Data'!$B:$B,"gemini-2.0-flash",'Raw Data'!$C:$C,"0.5",'Raw Data'!$D:$D,"0.5",'Raw Data'!$E:$E,"30") -> 0 | I9: =A9 & " (T:" & B9 & ", p:" & C9 & ", k:" & D9 & ")" -> 0 | J9: =JERARQUIA.EQV(E9,$E$2:$E$37,0) -> 0 | K9: =JERARQUIA.EQV(F9,$F$2:$F$37,1) -> 0 | L9: =JERARQUIA.EQV(G9,$G$2:$G$37,1) -> 0 | M9: =JERARQUIA.EQV(H9,$H$2:$H$37,1) -> 0 | N9: =PROMEDIO(J9,K9,L9,M9) -> 0 | O9: =SI(N9=MIN($N$2:$N$37),"Yes","") -> 0 | P9: =SI(N9=MIN.SI.CONJUNTO($N$2:$N$37,$A$2:$A$37,A9),"Yes","") -> 0
A10: gemini-2.0-flash | B10: 0.5 | C10: 0.1 | D10: 10 | E10: =PROMEDIO.SI.CONJUNTO('Raw Data'!$N:$N,'Raw Data'!$B:$B,"gemini-2.0-flash",'Raw Data'!$C:$C,"0.5",'Raw Data'!$D:$D,"0.1",'Raw Data'!$E:$E,"10") -> 0 | F10: =PROMEDIO.SI.CONJUNTO('Raw Data'!$J:$J,'Raw Data'!$B:$B,"gemini-2.0-flash",'Raw Data'!$C:$C,"0.5",'Raw Data'!$D:$D,"0.1",'Raw Data'!$E:$E,"10") -> 0 | G10: =PROMEDIO.SI.CONJUNTO('Raw Data'!$K:$K,'Raw Data'!$B:$B,"gemini-2.0-flash",'Raw Data'!$C:$C,"0.5",'Raw Data'!$D:$D,"0.1",'Raw Data'!$E:$E,"10") -> 0 | H10: =PROMEDIO.SI.CONJUNTO('Raw Data'!$O:$O,'Raw Data'!$B:$B,"gemini-2.0-flash",'Raw Data'!$C:$C,"0.5",'Raw Data'!$D:$D,"0.1",'Raw Data'!$E:$E,"10") -> 0 | I10: =A10 & " (T:" & B10 & ", p:" & C10 & ", k:" & D10 & ")" -> 0 | J10: =JERARQUIA.EQV(E10,$E$2:$E$37,0) -> 0 | K10: =JERARQUIA.EQV(F10,$F$2:$F$37,1) -> 0 | L10: =JERARQUIA.EQV(G10,$G$2:$G$37,1) -> 0 | M10: =JERARQUIA.EQV(H10,$H$2:$H$37,1) -> 0 | N10: =PROMEDIO(J10,K10,L10,M10) -> 0 | O10: =SI(N10=MIN($N$2:$N$37),"Yes","") -> 0 | P10: =SI(N10=MIN.SI.CONJUNTO($N$2:$N$37,$A$2:$A$37,A10),"Yes","") -> 0
A11: gemini-2.0-flash | B11: 0 | C11: 0.95 | D11: 100 | E11: =PROMEDIO.SI.CONJUNTO('Raw Data'!$N:$N,'Raw Data'!$B:$B,"gemini-2.0-flash",'Raw Data'!$C:$C,"0.0",'Raw Data'!$D:$D,"0.95",'Raw Data'!$E:$E,"100") -> 0 | F11: =PROMEDIO.SI.CONJUNTO('Raw Data'!$J:$J,'Raw Data'!$B:$B,"gemini-2.0-flash",'Raw Data'!$C:$C,"0.0",'Raw Data'!$D:$D,"0.95",'Raw Data'!$E:$E,"100") -> 0 | G11: =PROMEDIO.SI.CONJUNTO('Raw Data'!$K:$K,'Raw Data'!$B:$B,"gemini-2.0-flash",'Raw Data'!$C:$C,"0.0",'Raw Data'!$D:$D,"0.95",'Raw Data'!$E:$E,"100") -> 0 | H11: =PROMEDIO.SI.CONJUNTO('Raw Data'!$O:$O,'Raw Data'!$B:$B,"gemini-2.0-flash",'Raw Data'!$C:$C,"0.0",'Raw Data'!$D:$D,"0.95",'Raw Data'!$E:$E,"100") -> 0 | I11: =A11 & " (T:" & B11 & ", p:" & C11 & ", k:" & D11 & ")" -> 0 | J11: =JERARQUIA.EQV(E11,$E$2:$E$37,0) -> 0 | K11: =JERARQUIA.EQV(F11,$F$2:$F$37,1) -> 0 | L11: =JERARQUIA.EQV(G11,$G$2:$G$37,1) -> 0 | M11: =JERARQUIA.EQV(H11,$H$2:$H$37,1) -> 0 | N11: =PROMEDIO(J11,K11,L11,M11) -> 0 | O11: =SI(N11=MIN($N$2:$N$37),"Yes","") -> 0 | P11: =SI(N11=MIN.SI.CONJUNTO($N$2:$N$37,$A$2:$A$37,A11),"Yes","") -> 0
A12: gemini-2.0-flash | B12: 0 | C12: 0.5 | D12: 30 | E12: =PROMEDIO.SI.CONJUNTO('Raw Data'!$N:$N,'Raw Data'!$B:$B,"gemini-2.0-flash",'Raw Data'!$C:$C,"0.0",'Raw Data'!$D:$D,"0.5",'Raw Data'!$E:$E,"30") -> 0 | F12: =PROMEDIO.SI.CONJUNTO('Raw Data'!$J:$J,'Raw Data'!$B:$B,"gemini-2.0-flash",'Raw Data'!$C:$C,"0.0",'Raw Data'!$D:$D,"0.5",'Raw Data'!$E:$E,"30") -> 0 | G12: =PROMEDIO.SI.CONJUNTO('Raw Data'!$K:$K,'Raw Data'!$B:$B,"gemini-2.0-flash",'Raw Data'!$C:$C,"0.0",'Raw Data'!$D:$D,"0.5",'Raw Data'!$E:$E,"30") -> 0 | H12: =PROMEDIO.SI.CONJUNTO('Raw Data'!$O:$O,'Raw Data'!$B:$B,"gemini-2.0-flash",'Raw Data'!$C:$C,"0.0",'Raw Data'!$D:$D,"0.5",'Raw Data'!$E:$E,"30") -> 0 | I12: =A12 & " (T:" & B12 & ", p:" & C12 & ", k:" & D12 & ")" -> 0 | J12: =JERARQUIA.EQV(E12,$E$2:$E$37,0) -> 0 | K12: =JERARQUIA.EQV(F12,$F$2:$F$37,1) -> 0 | L12: =JERARQUIA.EQV(G12,$G$2:$G$37,1) -> 0 | M12: =JERARQUIA.EQV(H12,$H$2:$H$37,1) -> 0 | N12: =PROMEDIO(J12,K12,L12,M12) -> 0 | O12: =SI(N12=MIN($N$2:$N$37),"Yes","") -> 0 | P12: =SI(N12=MIN.SI.CONJUNTO($N$2:$N$37,$A$2:$A$37,A12),"Yes","") -> 0
A13: gemini-2.0-flash | B13: 0 | C13: 0.1 | D13: 10 | E13: =PROMEDIO.SI.CONJUNTO('Raw Data'!$N:$N,'Raw Data'!$B:$B,"gemini-2.0-flash",'Raw Data'!$C:$C,"0.0",'Raw Data'!$D:$D,"0.1",'Raw Data'!$E:$E,"10") -> 0 | F13: =PROMEDIO.SI.CONJUNTO('Raw Data'!$J:$J,'Raw Data'!$B:$B,"gemini-2.0-flash",'Raw Data'!$C:$C,"0.0",'Raw Data'!$D:$D,"0.1",'Raw Data'!$E:$E,"10") -> 0 | G13: =PROMEDIO.SI.CONJUNTO('Raw Data'!$K:$K,'Raw Data'!$B:$B,"gemini-2.0-flash",'Raw Data'!$C:$C,"0.0",'Raw Data'!$D:$D,"0.1",'Raw Data'!$E:$E,"10") -> 0 | H13: =PROMEDIO.SI.CONJUNTO('Raw Data'!$O:$O,'Raw Data'!$B:$B,"gemini-2.0-flash",'Raw Data'!$C:$C,"0.0",'Raw Data'!$D:$D,"0.1",'Raw Data'!$E:$E,"10") -> 0 | I13: =A13 & " (T:" & B13 & ", p:" & C13 & ", k:" & D13 & ")" -> 0 | J13: =JERARQUIA.EQV(E13,$E$2:$E$37,0) -> 0 | K13: =JERARQUIA.EQV(F13,$F$2:$F$37,1) -> 0 | L13: =JERARQUIA.EQV(G13,$G$2:$G$37,1) -> 0 | M13: =JERARQUIA.EQV(H13,$H$2:$H$37,1) -> 0 | N13: =PROMEDIO(J13,K13,L13,M13) -> 0 | O13: =SI(N13=MIN($N$2:$N$37),"Yes","") -> 0 | P13: =SI(N13=MIN.SI.CONJUNTO($N$2:$N$37,$A$2:$A$37,A13),"Yes","") -> 0
A14: gemini-2.0-flash-lite | B14: 0 | C14: 0.1 | D14: 10 | E14: =PROMEDIO.SI.CONJUNTO('Raw Data'!$N:$N,'Raw Data'!$B:$B,"gemini-2.0-flash-lite",'Raw Data'!$C:$C,"0.0",'Raw Data'!$D:$D,"0.1",'Raw Data'!$E:$E,"10") -> 0 | F14: =PROMEDIO.SI.CONJUNTO('Raw Data'!$J:$J,'Raw Data'!$B:$B,"gemini-2.0-flash-lite",'Raw Data'!$C:$C,"0.0",'Raw Data'!$D:$D,"0.1",'Raw Data'!$E:$E,"10") -> 0 | G14: =PROMEDIO.SI.CONJUNTO('Raw Data'!$K:$K,'Raw Data'!$B:$B,"gemini-2.0-flash-lite",'Raw Data'!$C:$C,"0.0",'Raw Data'!$D:$D,"0.1",'Raw Data'!$E:$E,"10") -> 0 | H14: =PROMEDIO.SI.CONJUNTO('Raw Data'!$O:$O,'Raw Data'!$B:$B,"gemini-2.0-flash-lite",'Raw Data'!$C:$C,"0.0",'Raw Data'!$D:$D,"0.1",'Raw Data'!$E:$E,"10") -> 0 | I14: =A14 & " (T:" & B14 & ", p:" & C14 & ", k:" & D14 & ")" -> 0 | J14: =JERARQUIA.EQV(E14,$E$2:$E$37,0) -> 0 | K14: =JERARQUIA.EQV(F14,$F$2:$F$37,1) -> 0 | L14: =JERARQUIA.EQV(G14,$G$2:$G$37,1) -> 0 | M14: =JERARQUIA.EQV(H14,$H$2:$H$37,1) -> 0 | N14: =PROMEDIO(J14,K14,L14,M14) -> 0 | O14: =SI(N14=MIN($N$2:$N$37),"Yes","") -> 0 | P14: =SI(N14=MIN.SI.CONJUNTO($N$2:$N$37,$A$2:$A$37,A14),"Yes","") -> 0
A15: gemini-2.0-flash-lite | B15: 2 | C15: 0.5 | D15: 30 | E15: =PROMEDIO.SI.CONJUNTO('Raw Data'!$N:$N,'Raw Data'!$B:$B,"gemini-2.0-flash-lite",'Raw Data'!$C:$C,"2.0",'Raw Data'!$D:$D,"0.5",'Raw Data'!$E:$E,"30") -> 0 | F15: =PROMEDIO.SI.CONJUNTO('Raw Data'!$J:$J,'Raw Data'!$B:$B,"gemini-2.0-flash-lite",'Raw Data'!$C:$C,"2.0",'Raw Data'!$D:$D,"0.5",'Raw Data'!$E:$E,"30") -> 0 | G15: =PROMEDIO.SI.CONJUNTO('Raw Data'!$K:$K,'Raw Data'!$B:$B,"gemini-2.0-flash-lite",'Raw Data'!$C:$C,"2.0",'Raw Data'!$D:$D,"0.5",'Raw Data'!$E:$E,"30") -> 0 | H15: =PROMEDIO.SI.CONJUNTO('Raw Data'!$O:$O,'Raw Data'!$B:$B,"gemini-2.0-flash-lite",'Raw Data'!$C:$C,"2.0",'Raw Data'!$D:$D,"0.5",'Raw Data'!$E:$E,"30") -> 0 | I15: =A15 & " (T:" & B15 & ", p:" & C15 & ", k:" & D15 & ")" -> 0 | J15: =JERARQUIA.EQV(E15,$E$2:$E$37,0) -> 0 | K15: =JERARQUIA.EQV(F15,$F$2:$F$37,1) -> 0 | L15: =JERARQUIA.EQV(G15,$G$2:$G$37,1) -> 0 | M15: =JERARQUIA.EQV(H15,$H$2:$H$37,1) -> 0 | N15: =PROMEDIO(J15,K15,L15,M15) -> 0 | O15: =SI(N15=MIN($N$2:$N$37),"Yes","") -> 0 | P15: =SI(N15=MIN.SI.CONJUNTO($N$2:$N$37,$A$2:$A$37,A15),"Yes","") -> 0
A16: gemini-2.0-flash-lite | B16: 2 | C16: 0.1 | D16: 10 | E16: =PROMEDIO.SI.CONJUNTO('Raw Data'!$N:$N,'Raw Data'!$B:$B,"gemini-2.0-flash-lite",'Raw Data'!$C:$C,"2.0",'Raw Data'!$D:$D,"0.1",'Raw Data'!$E:$E,"10") -> 0 | F16: =PROMEDIO.SI.CONJUNTO('Raw Data'!$J:$J,'Raw Data'!$B:$B,"gemini-2.0-flash-lite",'Raw Data'!$C:$C,"2.0",'Raw Data'!$D:$D,"0.1",'Raw Data'!$E:$E,"10") -> 0 | G16: =PROMEDIO.SI.CONJUNTO('Raw Data'!$K:$K,'Raw Data'!$B:$B,"gemini-2.0-flash-lite",'Raw Data'!$C:$C,"2.0",'Raw Data'!$D:$D,"0.1",'Raw Data'!$E:$E,"10") -> 0 | H16: =PROMEDIO.SI.CONJUNTO('Raw Data'!$O:$O,'Raw Data'!$B:$B,"gemini-2.0-flash-lite",'Raw Data'!$C:$C,"2.0",'Raw Data'!$D:$D,"0.1",'Raw Data'!$E:$E,"10") -> 0 | I16: =A16 & " (T:" & B16 & ", p:" & C16 & ", k:" & D16 & ")" -> 0 | J16: =JERARQUIA.EQV(E16,$E$2:$E$37,0) -> 0 | K16: =JERARQUIA.EQV(F16,$F$2:$F$37,1) -> 0 | L16: =JERARQUIA.EQV(G16,$G$2:$G$37,1) -> 0 | M16: =JERARQUIA.EQV(H16,$H$2:$H$37,1) -> 0 | N16: =PROMEDIO(J16,K16,L16,M16) -> 0 | O16: =SI(N16=MIN($N$2:$N$37),"Yes","") -> 0 | P16: =SI(N16=MIN.SI.CONJUNTO($N$2:$N$37,$A$2:$A$37,A16),"Yes","") -> 0
A17: gemini-2.0-flash-lite | B17: 1 | C17: 0.95 | D17: 100 | E17: =PROMEDIO.SI.CONJUNTO('Raw Data'!$N:$N,'Raw Data'!$B:$B,"gemini-2.0-flash-lite",'Raw Data'!$C:$C,"1.0",'Raw Data'!$D:$D,"0.95",'Raw Data'!$E:$E,"100") -> 0 | F17: =PROMEDIO.SI.CONJUNTO('Raw Data'!$J:$J,'Raw Data'!$B:$B,"gemini-2.0-flash-lite",'Raw Data'!$C:$C,"1.0",'Raw Data'!$D:$D,"0.95",'Raw Data'!$E:$E,"100") -> 0 | G17: =PROMEDIO.SI.CONJUNTO('Raw Data'!$K:$K,'Raw Data'!$B:$B,"gemini-2.0-flash-lite",'Raw Data'!$C:$C,"1.0",'Raw Data'!$D:$D,"0.95",'Raw Data'!$E:$E,"100") -> 0 | H17: =PROMEDIO.SI.CONJUNTO('Raw Data'!$O:$O,'Raw Data'!$B:$B,"gemini-2.0-flash-lite",'Raw Data'!$C:$C,"1.0",'Raw Data'!$D:$D,"0.95",'Raw Data'!$E:$E,"100") -> 0 | I17: =A17 & " (T:" & B17 & ", p:" & C17 & ", k:" & D17 & ")" -> 0 | J17: =JERARQUIA.EQV(E17,$E$2:$E$37,0) -> 0 | K17: =JERARQUIA.EQV(F17,$F$2:$F$37,1) -> 0 | L17: =JERARQUIA.EQV(G17,$G$2:$G$37,1) -> 0 | M17: =JERARQUIA.EQV(H17,$H$2:$H$37,1) -> 0 | N17: =PROMEDIO(J17,K17,L17,M17) -> 0 | O17: =SI(N17=MIN($N$2:$N$37),"Yes","") -> 0 | P17: =SI(N17=MIN.SI.CONJUNTO($N$2:$N$37,$A$2:$A$37,A17),"Yes","") -> 0
A18: gemini-2.0-flash-lite | B18: 1 | C18: 0.5 | D18: 30 | E18: =PROMEDIO.SI.CONJUNTO('Raw Data'!$N:$N,'Raw Data'!$B:$B,"gemini-2.0-flash-lite",'Raw Data'!$C:$C,"1.0",'Raw Data'!$D:$D,"0.5",'Raw Data'!$E:$E,"30") -> 0 | F18: =PROMEDIO.SI.CONJUNTO('Raw Data'!$J:$J,'Raw Data'!$B:$B,"gemini-2.0-flash-lite",'Raw Data'!$C:$C,"1.0",'Raw Data'!$D:$D,"0.5",'Raw Data'!$E:$E,"30") -> 0 | G18: =PROMEDIO.SI.CONJUNTO('Raw Data'!$K:$K,'Raw Data'!$B:$B,"gemini-2.0-flash-lite",'Raw Data'!$C:$C,"1.0",'Raw Data'!$D:$D,"0.5",'Raw Data'!$E:$E,"30") -> 0 | H18: =PROMEDIO.SI.CONJUNTO('Raw Data'!$O:$O,'Raw Data'!$B:$B,"gemini-2.0-flash-lite",'Raw Data'!$C:$C,"1.0",'Raw Data'!$D:$D,"0.5",'Raw Data'!$E:$E,"30") -> 0 | I18: =A18 & " (T:" & B18 & ", p:" & C18 & ", k:" & D18 & ")" -> 0 | J18: =JERARQUIA.EQV(E18,$E$2:$E$37,0) -> 0 | K18: =JERARQUIA.EQV(F18,$F$2:$F$37,1) -> 0 | L18: =JERARQUIA.EQV(G18,$G$2:$G$37,1) -> 0 | M18: =JERARQUIA.EQV(H18,$H$2:$H$37,1) -> 0 | N18: =PROMEDIO(J18,K18,L18,M18) -> 0 | O18: =SI(N18=MIN($N$2:$N$37),"Yes","") -> 0 | P18: =SI(N18=MIN.SI.CONJUNTO($N$2:$N$37,$A$2:$A$37,A18),"Yes","") -> 0
A19: gemini-2.0-flash-lite | B19: 1 | C19: 0.1 | D19: 10 | E19: =PROMEDIO.SI.CONJUNTO('Raw Data'!$N:$N,'Raw Data'!$B:$B,"gemini-2.0-flash-lite",'Raw Data'!$C:$C,"1.0",'Raw Data'!$D:$D,"0.1",'Raw Data'!$E:$E,"10") -> 0 | F19: =PROMEDIO.SI.CONJUNTO('Raw Data'!$J:$J,'Raw Data'!$B:$B,"gemini-2.0-flash-lite",'Raw Data'!$C:$C,"1.0",'Raw Data'!$D:$D,"0.1",'Raw Data'!$E:$E,"10") -> 0 | G19: =PROMEDIO.SI.CONJUNTO('Raw Data'!$K:$K,'Raw Data'!$B:$B,"gemini-2.0-flash-lite",'Raw Data'!$C:$C,"1.0",'Raw Data'!$D:$D,"0.1",'Raw Data'!$E:$E,"10") -> 0 | H19: =PROMEDIO.SI.CONJUNTO('Raw Data'!$O:$O,'Raw Data'!$B:$B,"gemini-2.0-flash-lite",'Raw Data'!$C:$C,"1.0",'Raw Data'!$D:$D,"0.1",'Raw Data'!$E:$E,"10") -> 0 | I19: =A19 & " (T:" & B19 & ", p:" & C19 & ", k:" & D19 & ")" -> 0 | J19: =JERARQUIA.EQV(E19,$E$2:$E$37,0) -> 0 | K19: =JERARQUIA.EQV(F19,$F$2:$F$37,1) -> 0 | L19: =JERARQUIA.EQV(G19,$G$2:$G$37,1) -> 0 | M19: =JERARQUIA.EQV(H19,$H$2:$H$37,1) -> 0 | N19: =PROMEDIO(J19,K19,L19,M19) -> 0 | O19: =SI(N19=MIN($N$2:$N$37),"Yes","") -> 0 | P19: =SI(N19=MIN.SI.CONJUNTO($N$2:$N$37,$A$2:$A$37,A19),"Yes","") -> 0
A20: gemini-2.0-flash-lite | B20: 0.5 | C20: 0.95 | D20: 100 | E20: =PROMEDIO.SI.CONJUNTO('Raw Data'!$N:$N,'Raw Data'!$B:$B,"gemini-2.0-flash-lite",'Raw Data'!$C:$C,"0.5",'Raw Data'!$D:$D,"0.95",'Raw Data'!$E:$E,"100") -> 0 | F20: =PROMEDIO.SI.CONJUNTO('Raw Data'!$J:$J,'Raw Data'!$B:$B,"gemini-2.0-flash-lite",'Raw Data'!$C:$C,"0.5",'Raw Data'!$D:$D,"0.95",'Raw Data'!$E:$E,"100") -> 0 | G20: =PROMEDIO.SI.CONJUNTO('Raw Data'!$K:$K,'Raw Data'!$B:$B,"gemini-2.0-flash-lite",'Raw Data'!$C:$C,"0.5",'Raw Data'!$D:$D,"0.95",'Raw Data'!$E:$E,"100") -> 0 | H20: =PROMEDIO.SI.CONJUNTO('Raw Data'!$O:$O,'Raw Data'!$B:$B,"gemini-2.0-flash-lite",'Raw Data'!$C:$C,"0.5",'Raw Data'!$D:$D,"0.95",'Raw Data'!$E:$E,"100") -> 0 | I20: =A20 & " (T:" & B20 & ", p:" & C20 & ", k:" & D20 & ")" -> 0 | J20: =JERARQUIA.EQV(E20,$E$2:$E$37,0) -> 0 | K20: =JERARQUIA.EQV(F20,$F$2:$F$37,1) -> 0 | L20: =JERARQUIA.EQV(G20,$G$2:$G$37,1) -> 0 | M20: =JERARQUIA.EQV(H20,$H$2:$H$37,1) -> 0 | N20: =PROMEDIO(J20,K20,L20,M20) -> 0 | O20: =SI(N20=MIN($N$2:$N$37),"Yes","") -> 0 | P20: =SI(N20=MIN.SI.CONJUNTO($N$2:$N$37,$A$2:$A$37,A20),"Yes","") -> 0
A21: gemini-2.0-flash-lite | B21: 0.5 | C21: 0.5 | D21: 30 | E21: =PROMEDIO.SI.CONJUNTO('Raw Data'!$N:$N,'Raw Data'!$B:$B,"gemini-2.0-flash-lite",'Raw Data'!$C:$C,"0.5",'Raw Data'!$D:$D,"0.5",'Raw Data'!$E:$E,"30") -> 0 | F21: =PROMEDIO.SI.CONJUNTO('Raw Data'!$J:$J,'Raw Data'!$B:$B,"gemini-2.0-flash-lite",'Raw Data'!$C:$C,"0.5",'Raw Data'!$D:$D,"0.5",'Raw Data'!$E:$E,"30") -> 0 | G21: =PROMEDIO.SI.CONJUNTO('Raw Data'!$K:$K,'Raw Data'!$B:$B,"gemini-2.0-flash-lite",'Raw Data'!$C:$C,"0.5",'Raw Data'!$D:$D,"0.5",'Raw Data'!$E:$E,"30") -> 0 | H21: =PROMEDIO.SI.CONJUNTO('Raw Data'!$O:$O,'Raw Data'!$B:$B,"gemini-2.0-flash-lite",'Raw Data'!$C:$C,"0.5",'Raw Data'!$D:$D,"0.5",'Raw Data'!$E:$E,"30") -> 0 | I21: =A21 & " (T:" & B21 & ", p:" & C21 & ", k:" & D21 & ")" -> 0 | J21: =JERARQUIA.EQV(E21,$E$2:$E$37,0) -> 0 | K21: =JERARQUIA.EQV(F21,$F$2:$F$37,1) -> 0 | L21: =JERARQUIA.EQV(G21,$G$2:$G$37,1) -> 0 | M21: =JERARQUIA.EQV(H21,$H$2:$H$37,1) -> 0 | N21: =PROMEDIO(J21,K21,L21,M21) -> 0 | O21: =SI(N21=MIN($N$2:$N$37),"Yes","") -> 0 | P21: =SI(N21=MIN.SI.CONJUNTO($N$2:$N$37,$A$2:$A$37,A21),"Yes","") -> 0
A22: gemini-2.0-flash-lite | B22: 0.5 | C22: 0.1 | D22: 10 | E22: =PROMEDIO.SI.CONJUNTO('Raw Data'!$N:$N,'Raw Data'!$B:$B,"gemini-2.0-flash-lite",'Raw Data'!$C:$C,"0.5",'Raw Data'!$D:$D,"0.1",'Raw Data'!$E:$E,"10") -> 0 | F22: =PROMEDIO.SI.CONJUNTO('Raw Data'!$J:$J,'Raw Data'!$B:$B,"gemini-2.0-flash-lite",'Raw Data'!$C:$C,"0.5",'Raw Data'!$D:$D,"0.1",'Raw Data'!$E:$E,"10") -> 0 | G22: =PROMEDIO.SI.CONJUNTO('Raw Data'!$K:$K,'Raw Data'!$B:$B,"gemini-2.0-flash-lite",'Raw Data'!$C:$C,"0.5",'Raw Data'!$D:$D,"0.1",'Raw Data'!$E:$E,"10") -> 0 | H22: =PROMEDIO.SI.CONJUNTO('Raw Data'!$O:$O,'Raw Data'!$B:$B,"gemini-2.0-flash-lite",'Raw Data'!$C:$C,"0.5",'Raw Data'!$D:$D,"0.1",'Raw Data'!$E:$E,"10") -> 0 | I22: =A22 & " (T:" & B22 & ", p:" & C22 & ", k:" & D22 & ")" -> 0 | J22: =JERARQUIA.EQV(E22,$E$2:$E$37,0) -> 0 | K22: =JERARQUIA.EQV(F22,$F$2:$F$37,1) -> 0 | L22: =JERARQUIA.EQV(G22,$G$2:$G$37,1) -> 0 | M22: =JERARQUIA.EQV(H22,$H$2:$H$37,1) -> 0 | N22: =PROMEDIO(J22,K22,L22,M22) -> 0 | O22: =SI(N22=MIN($N$2:$N$37),"Yes","") -> 0 | P22: =SI(N22=MIN.SI.CONJUNTO($N$2:$N$37,$A$2:$A$37,A22),"Yes","") -> 0
A23: gemini-2.0-flash-lite | B23: 0 | C23: 0.95 | D23: 100 | E23: =PROMEDIO.SI.CONJUNTO('Raw Data'!$N:$N,'Raw Data'!$B:$B,"gemini-2.0-flash-lite",'Raw Data'!$C:$C,"0.0",'Raw Data'!$D:$D,"0.95",'Raw Data'!$E:$E,"100") -> 0 | F23: =PROMEDIO.SI.CONJUNTO('Raw Data'!$J:$J,'Raw Data'!$B:$B,"gemini-2.0-flash-lite",'Raw Data'!$C:$C,"0.0",'Raw Data'!$D:$D,"0.95",'Raw Data'!$E:$E,"100") -> 0 | G23: =PROMEDIO.SI.CONJUNTO('Raw Data'!$K:$K,'Raw Data'!$B:$B,"gemini-2.0-flash-lite",'Raw Data'!$C:$C,"0.0",'Raw Data'!$D:$D,"0.95",'Raw Data'!$E:$E,"100") -> 0 | H23: =PROMEDIO.SI.CONJUNTO('Raw Data'!$O:$O,'Raw Data'!$B:$B,"gemini-2.0-flash-lite",'Raw Data'!$C:$C,"0.0",'Raw Data'!$D:$D,"0.95",'Raw Data'!$E:$E,"100") -> 0 | I23: =A23 & " (T:" & B23 & ", p:" & C23 & ", k:" & D23 & ")" -> 0 | J23: =JERARQUIA.EQV(E23,$E$2:$E$37,0) -> 0 | K23: =JERARQUIA.EQV(F23,$F$2:$F$37,1) -> 0 | L23: =JERARQUIA.EQV(G23,$G$2:$G$37,1) -> 0 | M23: =JERARQUIA.EQV(H23,$H$2:$H$37,1) -> 0 | N23: =PROMEDIO(J23,K23,L23,M23) -> 0 | O23: =SI(N23=MIN($N$2:$N$37),"Yes","") -> 0 | P23: =SI(N23=MIN.SI.CONJUNTO($N$2:$N$37,$A$2:$A$37,A23),"Yes","") -> 0
A24: gemini-2.0-flash-lite | B24: 0 | C24: 0.5 | D24: 30 | E24: =PROMEDIO.SI.CONJUNTO('Raw Data'!$N:$N,'Raw Data'!$B:$B,"gemini-2.0-flash-lite",'Raw Data'!$C:$C,"0.0",'Raw Data'!$D:$D,"0.5",'Raw Data'!$E:$E,"30") -> 0 | F24: =PROMEDIO.SI.CONJUNTO('Raw Data'!$J:$J,'Raw Data'!$B:$B,"gemini-2.0-flash-lite",'Raw Data'!$C:$C,"0.0",'Raw Data'!$D:$D,"0.5",'Raw Data'!$E:$E,"30") -> 0 | G24: =PROMEDIO.SI.CONJUNTO('Raw Data'!$K:$K,'Raw Data'!$B:$B,"gemini-2.0-flash-lite",'Raw Data'!$C:$C,"0.0",'Raw Data'!$D:$D,"0.5",'Raw Data'!$E:$E,"30") -> 0 | H24: =PROMEDIO.SI.CONJUNTO('Raw Data'!$O:$O,'Raw Data'!$B:$B,"gemini-2.0-flash-lite",'Raw Data'!$C:$C,"0.0",'Raw Data'!$D:$D,"0.5",'Raw Data'!$E:$E,"30") -> 0 | I24: =A24 & " (T:" & B24 & ", p:" & C24 & ", k:" & D24 & ")" -> 0 | J24: =JERARQUIA.EQV(E24,$E$2:$E$37,0) -> 0 | K24: =JERARQUIA.EQV(F24,$F$2:$F$37,1) -> 0 | L24: =JERARQUIA.EQV(G24,$G$2:$G$37,1) -> 0 | M24: =JERARQUIA.EQV(H24,$H$2:$H$37,1) -> 0 | N24: =PROMEDIO(J24,K24,L24,M24) -> 0 | O24: =SI(N24=MIN($N$2:$N$37),"Yes","") -> 0 | P24: =SI(N24=MIN.SI.CONJUNTO($N$2:$N$37,$A$2:$A$37,A24),"Yes","") -> 0
A25: gemini-2.0-flash-lite | B25: 2 | C25: 0.95 | D25: 100 | E25: =PROMEDIO.SI.CONJUNTO('Raw Data'!$N:$N,'Raw Data'!$B:$B,"gemini-2.0-flash-lite",'Raw Data'!$C:$C,"2.0",'Raw Data'!$D:$D,"0.95",'Raw Data'!$E:$E,"100") -> 0 | F25: =PROMEDIO.SI.CONJUNTO('Raw Data'!$J:$J,'Raw Data'!$B:$B,"gemini-2.0-flash-lite",'Raw Data'!$C:$C,"2.0",'Raw Data'!$D:$D,"0.95",'Raw Data'!$E:$E,"100") -> 0 | G25: =PROMEDIO.SI.CONJUNTO('Raw Data'!$K:$K,'Raw Data'!$B:$B,"gemini-2.0-flash-lite",'Raw Data'!$C:$C,"2.0",'Raw Data'!$D:$D,"0.95",'Raw Data'!$E:$E,"100") -> 0 | H25: =PROMEDIO.SI.CONJUNTO('Raw Data'!$O:$O,'Raw Data'!$B:$B,"gemini-2.0-flash-lite",'Raw Data'!$C:$C,"2.0",'Raw Data'!$D:$D,"0.95",'Raw Data'!$E:$E,"100") -> 0 | I25: =A25 & " (T:" & B25 & ", p:" & C25 & ", k:" & D25 & ")" -> 0 | J25: =JERARQUIA.EQV(E25,$E$2:$E$37,0) -> 0 | K25: =JERARQUIA.EQV(F25,$F$2:$F$37,1) -> 0 | L25: =JERARQUIA.EQV(G25,$G$2:$G$37,1) -> 0 | M25: =JERARQUIA.EQV(H25,$H$2:$H$37,1) -> 0 | N25: =PROMEDIO(J25,K25,L25,M25) -> 0 | O25: =SI(N25=MIN($N$2:$N$37),"Yes","") -> 0 | P25: =SI(N25=MIN.SI.CONJUNTO($N$2:$N$37,$A$2:$A$37,A25),"Yes","") -> 0
A26: gemini-2.0-pro-exp-02-05 | B26: 2 | C26: 0.1 | D26: 10 | E26: =PROMEDIO.SI.CONJUNTO('Raw Data'!$N:$N,'Raw Data'!$B:$B,"gemini-2.0-pro-exp-02-05",'Raw Data'!$C:$C,"2.0",'Raw Data'!$D:$D,"0.1",'Raw Data'!$E:$E,"10") -> 0 | F26: =PROMEDIO.SI.CONJUNTO('Raw Data'!$J:$J,'Raw Data'!$B:$B,"gemini-2.0-pro-exp-02-05",'Raw Data'!$C:$C,"2.0",'Raw Data'!$D:$D,"0.1",'Raw Data'!$E:$E,"10") -> 0 | G26: =PROMEDIO.SI.CONJUNTO('Raw Data'!$K:$K,'Raw Data'!$B:$B,"gemini-2.0-pro-exp-02-05",'Raw Data'!$C:$C,"2.0",'Raw Data'!$D:$D,"0.1",'Raw Data'!$E:$E,"10") -> 0 | H26: =PROMEDIO.SI.CONJUNTO('Raw Data'!$O:$O,'Raw Data'!$B:$B,"gemini-2.0-pro-exp-02-05",'Raw Data'!$C:$C,"2.0",'Raw Data'!$D:$D,"0.1",'Raw Data'!$E:$E,"10") -> 0 | I26: =A26 & " (T:" & B26 & ", p:" & C26 & ", k:" & D26 & ")" -> 0 | J26: =JERARQUIA.EQV(E26,$E$2:$E$37,0) -> 0 | K26: =JERARQUIA.EQV(F26,$F$2:$F$37,1) -> 0 | L26: =JERARQUIA.EQV(G26,$G$2:$G$37,1) -> 0 | M26: =JERARQUIA.EQV(H26,$H$2:$H$37,1) -> 0 | N26: =PROMEDIO(J26,K26,L26,M26) -> 0 | O26: =SI(N26=MIN($N$2:$N$37),"Yes","") -> 0 | P26: =SI(N26=MIN.SI.CONJUNTO($N$2:$N$37,$A$2:$A$37,A26),"Yes","") -> 0
A27: gemini-2.0-pro-exp-02-05 | B27: 1 | C27: 0.95 | D27: 100 | E27: =PROMEDIO.SI.CONJUNTO('Raw Data'!$N:$N,'Raw Data'!$B:$B,"gemini-2.0-pro-exp-02-05",'Raw Data'!$C:$C,"1.0",'Raw Data'!$D:$D,"0.95",'Raw Data'!$E:$E,"100") -> 0 | F27: =PROMEDIO.SI.CONJUNTO('Raw Data'!$J:$J,'Raw Data'!$B:$B,"gemini-2.0-pro-exp-02-05",'Raw Data'!$C:$C,"1.0",'Raw Data'!$D:$D,"0.95",'Raw Data'!$E:$E,"100") -> 0 | G27: =PROMEDIO.SI.CONJUNTO('Raw Data'!$K:$K,'Raw Data'!$B:$B,"gemini-2.0-pro-exp-02-05",'Raw Data'!$C:$C,"1.0",'Raw Data'!$D:$D,"0.95",'Raw Data'!$E:$E,"100") -> 0 | H27: =PROMEDIO.SI.CONJUNTO('Raw Data'!$O:$O,'Raw Data'!$B:$B,"gemini-2.0-pro-exp-02-05",'Raw Data'!$C:$C,"1.0",'Raw Data'!$D:$D,"0.95",'Raw Data'!$E:$E,"100") -> 0 | I27: =A27 & " (T:" & B27 & ", p:" & C27 & ", k:" & D27 & ")" -> 0 | J27: =JERARQUIA.EQV(E27,$E$2:$E$37,0) -> 0 | K27: =JERARQUIA.EQV(F27,$F$2:$F$37,1) -> 0 | L27: =JERARQUIA.EQV(G27,$G$2:$G$37,1) -> 0 | M27: =JERARQUIA.EQV(H27,$H$2:$H$37,1) -> 0 | N27: =PROMEDIO(J27,K27,L27,M27) -> 0 | O27: =SI(N27=MIN($N$2:$N$37),"Yes","") -> 0 | P27: =SI(N27=MIN.SI.CONJUNTO($N$2:$N$37,$A$2:$A$37,A27),"Yes","") -> 0
A28: gemini-2.0-pro-exp-02-05 | B28: 1 | C28: 0.5 | D28: 30 | E28: =PROMEDIO.SI.CONJUNTO('Raw Data'!$N:$N,'Raw Data'!$B:$B,"gemini-2.0-pro-exp-02-05",'Raw Data'!$C:$C,"1.0",'Raw Data'!$D:$D,"0.5",'Raw Data'!$E:$E,"30") -> 0 | F28: =PROMEDIO.SI.CONJUNTO('Raw Data'!$J:$J,'Raw Data'!$B:$B,"gemini-2.0-pro-exp-02-05",'Raw Data'!$C:$C,"1.0",'Raw Data'!$D:$D,"0.5",'Raw Data'!$E:$E,"30") -> 0 | G28: =PROMEDIO.SI.CONJUNTO('Raw Data'!$K:$K,'Raw Data'!$B:$B,"gemini-2.0-pro-exp-02-05",'Raw Data'!$C:$C,"1.0",'Raw Data'!$D:$D,"0.5",'Raw Data'!$E:$E,"30") -> 0 | H28: =PROMEDIO.SI.CONJUNTO('Raw Data'!$O:$O,'Raw Data'!$B:$B,"gemini-2.0-pro-exp-02-05",'Raw Data'!$C:$C,"1.0",'Raw Data'!$D:$D,"0.5",'Raw Data'!$E:$E,"30") -> 0 | I28: =A28 & " (T:" & B28 & ", p:" & C28 & ", k:" & D28 & ")" -> 0 | J28: =JERARQUIA.EQV(E28,$E$2:$E$37,0) -> 0 | K28: =JERARQUIA.EQV(F28,$F$2:$F$37,1) -> 0 | L28: =JERARQUIA.EQV(G28,$G$2:$G$37,1) -> 0 | M28: =JERARQUIA.EQV(H28,$H$2:$H$37,1) -> 0 | N28: =PROMEDIO(J28,K28,L28,M28) -> 0 | O28: =SI(N28=MIN($N$2:$N$37),"Yes","") -> 0 | P28: =SI(N28=MIN.SI.CONJUNTO($N$2:$N$37,$A$2:$A$37,A28),"Yes","") -> 0
A29: gemini-2.0-pro-exp-02-05 | B29: 1 | C29: 0.1 | D29: 10 | E29: =PROMEDIO.SI.CONJUNTO('Raw Data'!$N:$N,'Raw Data'!$B:$B,"gemini-2.0-pro-exp-02-05",'Raw Data'!$C:$C,"1.0",'Raw Data'!$D:$D,"0.1",'Raw Data'!$E:$E,"10") -> 0 | F29: =PROMEDIO.SI.CONJUNTO('Raw Data'!$J:$J,'Raw Data'!$B:$B,"gemini-2.0-pro-exp-02-05",'Raw Data'!$C:$C,"1.0",'Raw Data'!$D:$D,"0.1",'Raw Data'!$E:$E,"10") -> 0 | G29: =PROMEDIO.SI.CONJUNTO('Raw Data'!$K:$K,'Raw Data'!$B:$B,"gemini-2.0-pro-exp-02-05",'Raw Data'!$C:$C,"1.0",'Raw Data'!$D:$D,"0.1",'Raw Data'!$E:$E,"10") -> 0 | H29: =PROMEDIO.SI.CONJUNTO('Raw Data'!$O:$O,'Raw Data'!$B:$B,"gemini-2.0-pro-exp-02-05",'Raw Data'!$C:$C,"1.0",'Raw Data'!$D:$D,"0.1",'Raw Data'!$E:$E,"10") -> 0 | I29: =A29 & " (T:" & B29 & ", p:" & C29 & ", k:" & D29 & ")" -> 0 | J29: =JERARQUIA.EQV(E29,$E$2:$E$37,0) -> 0 | K29: =JERARQUIA.EQV(F29,$F$2:$F$37,1) -> 0 | L29: =JERARQUIA.EQV(G29,$G$2:$G$37,1) -> 0 | M29: =JERARQUIA.EQV(H29,$H$2:$H$37,1) -> 0 | N29: =PROMEDIO(J29,K29,L29,M29) -> 0 | O29: =SI(N29=MIN($N$2:$N$37),"Yes","") -> 0 | P29: =SI(N29=MIN.SI.CONJUNTO($N$2:$N$37,$A$2:$A$37,A29),"Yes","") -> 0
A30: gemini-2.0-pro-exp-02-05 | B30: 0.5 | C30: 0.95 | D30: 100 | E30: =PROMEDIO.SI.CONJUNTO('Raw Data'!$N:$N,'Raw Data'!$B:$B,"gemini-2.0-pro-exp-02-05",'Raw Data'!$C:$C,"0.5",'Raw Data'!$D:$D,"0.95",'Raw Data'!$E:$E,"100") -> 0 | F30: =PROMEDIO.SI.CONJUNTO('Raw Data'!$J:$J,'Raw Data'!$B:$B,"gemini-2.0-pro-exp-02-05",'Raw Data'!$C:$C,"0.5",'Raw Data'!$D:$D,"0.95",'Raw Data'!$E:$E,"100") -> 0 | G30: =PROMEDIO.SI.CONJUNTO('Raw Data'!$K:$K,'Raw Data'!$B:$B,"gemini-2.0-pro-exp-02-05",'Raw Data'!$C:$C,"0.5",'Raw Data'!$D:$D,"0.95",'Raw Data'!$E:$E,"100") -> 0 | H30: =PROMEDIO.SI.CONJUNTO('Raw Data'!$O:$O,'Raw Data'!$B:$B,"gemini-2.0-pro-exp-02-05",'Raw Data'!$C:$C,"0.5",'Raw Data'!$D:$D,"0.95",'Raw Data'!$E:$E,"100") -> 0 | I30: =A30 & " (T:" & B30 & ", p:" & C30 & ", k:" & D30 & ")" -> 0 | J30: =JERARQUIA.EQV(E30,$E$2:$E$37,0) -> 0 | K30: =JERARQUIA.EQV(F30,$F$2:$F$37,1) -> 0 | L30: =JERARQUIA.EQV(G30,$G$2:$G$37,1) -> 0 | M30: =JERARQUIA.EQV(H30,$H$2:$H$37,1) -> 0 | N30: =PROMEDIO(J30,K30,L30,M30) -> 0 | O30: =SI(N30=MIN($N$2:$N$37),"Yes","") -> 0 | P30: =SI(N30=MIN.SI.CONJUNTO($N$2:$N$37,$A$2:$A$37,A30),"Yes","") -> 0
A31: gemini-2.0-pro-exp-02-05 | B31: 0 | C31: 0.1 | D31: 10 | E31: =PROMEDIO.SI.CONJUNTO('Raw Data'!$N:$N,'Raw Data'!$B:$B,"gemini-2.0-pro-exp-02-05",'Raw Data'!$C:$C,"0.0",'Raw Data'!$D:$D,"0.1",'Raw Data'!$E:$E,"10") -> 0 | F31: =PROMEDIO.SI.CONJUNTO('Raw Data'!$J:$J,'Raw Data'!$B:$B,"gemini-2.0-pro-exp-02-05",'Raw Data'!$C:$C,"0.0",'Raw Data'!$D:$D,"0.1",'Raw Data'!$E:$E,"10") -> 0 | G31: =PROMEDIO.SI.CONJUNTO('Raw Data'!$K:$K,'Raw Data'!$B:$B,"gemini-2.0-pro-exp-02-05",'Raw Data'!$C:$C,"0.0",'Raw Data'!$D:$D,"0.1",'Raw Data'!$E:$E,"10") -> 0 | H31: =PROMEDIO.SI.CONJUNTO('Raw Data'!$O:$O,'Raw Data'!$B:$B,"gemini-2.0-pro-exp-02-05",'Raw Data'!$C:$C,"0.0",'Raw Data'!$D:$D,"0.1",'Raw Data'!$E:$E,"10") -> 0 | I31: =A31 & " (T:" & B31 & ", p:" & C31 & ", k:" & D31 & ")" -> 0 | J31: =JERARQUIA.EQV(E31,$E$2:$E$37,0) -> 0 | K31: =JERARQUIA.EQV(F31,$F$2:$F$37,1) -> 0 | L31: =JERARQUIA.EQV(G31,$G$2:$G$37,1) -> 0 | M31: =JERARQUIA.EQV(H31,$H$2:$H$37,1) -> 0 | N31: =PROMEDIO(J31,K31,L31,M31) -> 0 | O31: =SI(N31=MIN($N$2:$N$37),"Yes","") -> 0 | P31: =SI(N31=MIN.SI.CONJUNTO($N$2:$N$37,$A$2:$A$37,A31),"Yes","") -> 0
A32: gemini-2.0-pro-exp-02-05 | B32: 0.5 | C32: 0.1 | D32: 10 | E32: =PROMEDIO.SI.CONJUNTO('Raw Data'!$N:$N,'Raw Data'!$B:$B,"gemini-2.0-pro-exp-02-05",'Raw Data'!$C:$C,"0.5",'Raw Data'!$D:$D,"0.1",'Raw Data'!$E:$E,"10") -> 0 | F32: =PROMEDIO.SI.CONJUNTO('Raw Data'!$J:$J,'Raw Data'!$B:$B,"gemini-2.0-pro-exp-02-05",'Raw Data'!$C:$C,"0.5",'Raw Data'!$D:$D,"0.1",'Raw Data'!$E:$E,"10") -> 0 | G32: =PROMEDIO.SI.CONJUNTO('Raw Data'!$K:$K,'Raw Data'!$B:$B,"gemini-2.0-pro-exp-02-05",'Raw Data'!$C:$C,"0.5",'Raw Data'!$D:$D,"0.1",'Raw Data'!$E:$E,"10") -> 0 | H32: =PROMEDIO.SI.CONJUNTO('Raw Data'!$O:$O,'Raw Data'!$B:$B,"gemini-2.0-pro-exp-02-05",'Raw Data'!$C:$C,"0.5",'Raw Data'!$D:$D,"0.1",'Raw Data'!$E:$E,"10") -> 0 | I32: =A32 & " (T:" & B32 & ", p:" & C32 & ", k:" & D32 & ")" -> 0 | J32: =JERARQUIA.EQV(E32,$E$2:$E$37,0) -> 0 | K32: =JERARQUIA.EQV(F32,$F$2:$F$37,1) -> 0 | L32: =JERARQUIA.EQV(G32,$G$2:$G$37,1) -> 0 | M32: =JERARQUIA.EQV(H32,$H$2:$H$37,1) -> 0 | N32: =PROMEDIO(J32,K32,L32,M32) -> 0 | O32: =SI(N32=MIN($N$2:$N$37),"Yes","") -> 0 | P32: =SI(N32=MIN.SI.CONJUNTO($N$2:$N$37,$A$2:$A$37,A32),"Yes","") -> 0
